Workbook

Sheet SAA with CME
A1: SIX Asset Portfolio
B3: Correl | C3: US Large Cap | D3: Dev ex US | E3: EM | F3: UST | G3: US IG Corp Bond | H3: REITs
B4: US Large Cap | C4: 1 | D4: 0.895 | E4: 0.795 | F4: -0.33495 | G4: 0.27 | H4: 0.72
B5: Dev ex US | C5: 0.895 | D5: 1 | E5: 0.865 | F5: -0.29555 | G5: 0.39 | H5: 0.615
B6: EM | C6: 0.795 | D6: 0.865 | E6: 1 | F6: -0.2569 | G6: 0.415 | H6: 0.585
B7: UST | C7: -0.33495 | D7: -0.29555 | E7: -0.2569 | F7: 1 | G7: 0.535 | H7: -0.024645
B8: US IG Corp Bond | C8: 0.27 | D8: 0.39 | E8: 0.415 | F8: 0.535 | G8: 1 | H8: 0.425
B9: REITs | C9: 0.72 | D9: 0.615 | E9: 0.585 | F9: -0.024645 | G9: 0.425 | H9: 1
B11: E Return | C11: 0.0577395 | D11: 0.062829 | E11: 0.075861 | F11: 0.018441 | G11: 0.0304965 | H11: 0.058608
B12: Volatility | C12: 0.16566 | D12: 0.1988195 | E12: 0.240119 | F12: 0.1008315 | G12: 0.060962 | H12: 0.234245
J15: Define portfolio objectives and constraints
C16: =C3 | D16: =D3 | E16: =E3 | F16: =F3 | G16: =G3 | H16: =H3
B17: Weights | C17: 0.222942 | D17: 0.1 | E17: 0.341115 | F17: 0.1 | G17: 0.135943 | H17: 0.1 | I17: =SUM(C17:H17) | J17: Constraint | K17: 0.1 | L17: per asset
B18: E Return | C18: =C17*C11 | D18: =D17*D11 | E18: =E17*E11 | F18: =F17*F11 | G18: =G17*G11 | H18: =H17*H11 | I18: =SUM(C18:H18) | J18: Objective: Max Return
H19: Variance | I19: {=MMULT(MMULT(C17:H17*$C$12:$H$12,$C$4:$H$9),TRANSPOSE(C17:H17*$C$12:$H$12))}
H20: Volatility | I20: =SQRT(I19) | J20: For Risk Level: Medium | K20: 0.15
H21: Risk-Free Rate | I21: 0.03
H22: Sharpe Ratio | I22: =(I18-I21)/I20 | J22: Weights (blue) = Solver result: Max I18 by changing C17:H17, s.t. I17 = 100%, I20 <= K20, C17:H17 >= K17.

Sheet Index Returns
A1: Index | B1: US Large Cap | C1: Dev ex US | D1: EM | E1: UST | F1: US IG Corp Bond | G1: REITs
A2: 36585 | B2: -0.0096300858 | C2: 0.002358393 | D2: 0.002358393 | E2: -0.021243057 | F2: 0.0056581651 | G2: -0.028660244
A3: 36616 | B3: 0.045823842 | C3: 0.02320719 | D3: 0.02320719 | E3: -0.040337182 | F3: 0.0077365716 | G3: -0.0033643129
A4: 36644 | B4: -0.0072999361 | C4: -0.027483517 | D4: -0.027483517 | E4: -0.042514904 | F4: 0.006436328 | G4: 0.055385687
A5: 36677 | B5: -0.028714769 | C5: -0.040368748 | D5: -0.040368748 | E5: 0.075106628 | F5: -0.022235327 | G5: 0.037859265
A6: 36707 | B6: 0.035217747 | C6: 0.042731255 | D6: 0.042731255 | E6: -0.053285341 | F6: 0.027657174 | G6: 0.03229656
A7: 36738 | B7: 0.006699123 | C7: -0.0088846429 | D7: -0.0088846429 | E7: -0.0070970628 | F7: 0.013513591 | G7: 0.046883912
A8: 36769 | B8: 0.0073634753 | C8: -0.028449637 | D8: -0.028449637 | E8: -0.037646687 | F8: 0.012964601 | G8: 0.017230577
A9: 36798 | B9: -6.7194634e-06 | C9: -0.031463387 | D9: -0.031463387 | E9: -0.0046492537 | F9: 0.0056364753 | G9: -0.0099409611
A10: 36830 | B10: -0.057550427 | C10: -0.044308938 | D10: -0.044308938 | E10: -0.010420516 | F10: 0.0039797154 | G10: -0.027840079
A11: 36860 | B11: -0.014561193 | C11: -0.0051056651 | D11: -0.0051056651 | E11: -0.0037341299 | F11: 0.0038094361 | G11: -0.00075495409
A12: 36889 | B12: -0.033936814 | C12: -0.0084341113 | D12: -0.0084341113 | E12: -0.083370815 | F12: 0.021878738 | G12: 0.062460936
A13: 36922 | B13: 0.003531884 | C13: -0.0036590616 | D13: -0.0036590616 | E13: -0.015179395 | F13: 0.020431286 | G13: 0.025456538
... A204: 42734 | B204: 0.041212499 | C204: 0.016624934 | D204: 0.016531582 | E204: 0.16284783 | F204: -0.01093384 | G204: 0.022187854

Sheet Scenarios MPT
E1: Monthly Return | L1: Monthly Risk
A2: Scenario | B2: Scenario Name | C2: Start | D2: End | E2: US Large Cap | F2: Dev ex US | G2: EM | H2: UST | I2: US IG Corp Bond | J2: REITs | L2: US Large Cap | M2: Dev ex US | N2: EM | O2: UST | P2: US IG Corp Bond | Q2: REITs
A3: sector specific crash | B3: Dot-Com Bubble Burst | C3: 36526 | D3: 37621 | E3: =AVERAGEIFS('Index Returns'!$B$2:$B$204,'Index Returns'!$A$2:$A$204,">="&$C3,'Index Returns'!$A$2:$A$204,"<="&$D3) | F3: =AVERAGEIFS('Index Returns'!$C$2:$C$204,'Index Returns'!$A$2:$A$204,">="&$C3,'Index Returns'!$A$2:$A$204,"<="&$D3) | G3: =AVERAGEIFS('Index Returns'!$D$2:$D$204,'Index Returns'!$A$2:$A$204,">="&$C3,'Index Returns'!$A$2:$A$204,"<="&$D3) | H3: =AVERAGEIFS('Index Returns'!$E$2:$E$204,'Index Returns'!$A$2:$A$204,">="&$C3,'Index Returns'!$A$2:$A$204,"<="&$D3) | I3: =AVERAGEIFS('Index Returns'!$F$2:$F$204,'Index Returns'!$A$2:$A$204,">="&$C3,'Index Returns'!$A$2:$A$204,"<="&$D3) | J3: =AVERAGEIFS('Index Returns'!$G$2:$G$204,'Index Returns'!$A$2:$A$204,">="&$C3,'Index Returns'!$A$2:$A$204,"<="&$D3) | L3: {=_xlfn.STDEV.S(IF(('Index Returns'!$A$2:$A$204>=$C3)*('Index Returns'!$A$2:$A$204<=$D3),'Index Returns'!$B$2:$B$204))} | M3: {=_xlfn.STDEV.S(IF(('Index Returns'!$A$2:$A$204>=$C3)*('Index Returns'!$A$2:$A$204<=$D3),'Index Returns'!$C$2:$C$204))} | N3: {=_xlfn.STDEV.S(IF(('Index Returns'!$A$2:$A$204>=$C3)*('Index Returns'!$A$2:$A$204<=$D3),'Index Returns'!$D$2:$D$204))} | O3: {=_xlfn.STDEV.S(IF(('Index Returns'!$A$2:$A$204>=$C3)*('Index Returns'!$A$2:$A$204<=$D3),'Index Returns'!$E$2:$E$204))} | P3: {=_xlfn.STDEV.S(IF(('Index Returns'!$A$2:$A$204>=$C3)*('Index Returns'!$A$2:$A$204<=$D3),'Index Returns'!$F$2:$F$204))} | Q3: {=_xlfn.STDEV.S(IF(('Index Returns'!$A$2:$A$204>=$C3)*('Index Returns'!$A$2:$A$204<=$D3),'Index Returns'!$G$2:$G$204))}
A4: systemic financial crisis | B4: Global Financial Crisis | C4: 39083 | D4: 40178 | E4: =AVERAGEIFS('Index Returns'!$B$2:$B$204,'Index Returns'!$A$2:$A$204,">="&$C4,'Index Returns'!$A$2:$A$204,"<="&$D4) | F4: =AVERAGEIFS('Index Returns'!$C$2:$C$204,'Index Returns'!$A$2:$A$204,">="&$C4,'Index Returns'!$A$2:$A$204,"<="&$D4) | G4: =AVERAGEIFS('Index Returns'!$D$2:$D$204,'Index Returns'!$A$2:$A$204,">="&$C4,'Index Returns'!$A$2:$A$204,"<="&$D4) | H4: =AVERAGEIFS('Index Returns'!$E$2:$E$204,'Index Returns'!$A$2:$A$204,">="&$C4,'Index Returns'!$A$2:$A$204,"<="&$D4) | I4: =AVERAGEIFS('Index Returns'!$F$2:$F$204,'Index Returns'!$A$2:$A$204,">="&$C4,'Index Returns'!$A$2:$A$204,"<="&$D4) | J4: =AVERAGEIFS('Index Returns'!$G$2:$G$204,'Index Returns'!$A$2:$A$204,">="&$C4,'Index Returns'!$A$2:$A$204,"<="&$D4) | L4: {=_xlfn.STDEV.S(IF(('Index Returns'!$A$2:$A$204>=$C4)*('Index Returns'!$A$2:$A$204<=$D4),'Index Returns'!$B$2:$B$204))} | M4: {=_xlfn.STDEV.S(IF(('Index Returns'!$A$2:$A$204>=$C4)*('Index Returns'!$A$2:$A$204<=$D4),'Index Returns'!$C$2:$C$204))} | N4: {=_xlfn.STDEV.S(IF(('Index Returns'!$A$2:$A$204>=$C4)*('Index Returns'!$A$2:$A$204<=$D4),'Index Returns'!$D$2:$D$204))} | O4: {=_xlfn.STDEV.S(IF(('Index Returns'!$A$2:$A$204>=$C4)*('Index Returns'!$A$2:$A$204<=$D4),'Index Returns'!$E$2:$E$204))} | P4: {=_xlfn.STDEV.S(IF(('Index Returns'!$A$2:$A$204>=$C4)*('Index Returns'!$A$2:$A$204<=$D4),'Index Returns'!$F$2:$F$204))} | Q4: {=_xlfn.STDEV.S(IF(('Index Returns'!$A$2:$A$204>=$C4)*('Index Returns'!$A$2:$A$204<=$D4),'Index Returns'!$G$2:$G$204))}
A5: sovereign debt crisis | B5: European Debt Crisis | C5: 39814 | D5: 41639 | E5: =AVERAGEIFS('Index Returns'!$B$2:$B$204,'Index Returns'!$A$2:$A$204,">="&$C5,'Index Returns'!$A$2:$A$204,"<="&$D5) | F5: =AVERAGEIFS('Index Returns'!$C$2:$C$204,'Index Returns'!$A$2:$A$204,">="&$C5,'Index Returns'!$A$2:$A$204,"<="&$D5) | G5: =AVERAGEIFS('Index Returns'!$D$2:$D$204,'Index Returns'!$A$2:$A$204,">="&$C5,'Index Returns'!$A$2:$A$204,"<="&$D5) | H5: =AVERAGEIFS('Index Returns'!$E$2:$E$204,'Index Returns'!$A$2:$A$204,">="&$C5,'Index Returns'!$A$2:$A$204,"<="&$D5) | I5: =AVERAGEIFS('Index Returns'!$F$2:$F$204,'Index Returns'!$A$2:$A$204,">="&$C5,'Index Returns'!$A$2:$A$204,"<="&$D5) | J5: =AVERAGEIFS('Index Returns'!$G$2:$G$204,'Index Returns'!$A$2:$A$204,">="&$C5,'Index Returns'!$A$2:$A$204,"<="&$D5) | L5: {=_xlfn.STDEV.S(IF(('Index Returns'!$A$2:$A$204>=$C5)*('Index Returns'!$A$2:$A$204<=$D5),'Index Returns'!$B$2:$B$204))} | M5: {=_xlfn.STDEV.S(IF(('Index Returns'!$A$2:$A$204>=$C5)*('Index Returns'!$A$2:$A$204<=$D5),'Index Returns'!$C$2:$C$204))} | N5: {=_xlfn.STDEV.S(IF(('Index Returns'!$A$2:$A$204>=$C5)*('Index Returns'!$A$2:$A$204<=$D5),'Index Returns'!$D$2:$D$204))} | O5: {=_xlfn.STDEV.S(IF(('Index Returns'!$A$2:$A$204>=$C5)*('Index Returns'!$A$2:$A$204<=$D5),'Index Returns'!$E$2:$E$204))} | P5: {=_xlfn.STDEV.S(IF(('Index Returns'!$A$2:$A$204>=$C5)*('Index Returns'!$A$2:$A$204<=$D5),'Index Returns'!$F$2:$F$204))} | Q5: {=_xlfn.STDEV.S(IF(('Index Returns'!$A$2:$A$204>=$C5)*('Index Returns'!$A$2:$A$204<=$D5),'Index Returns'!$G$2:$G$204))}
A6: commodity price shock | B6: Oil Price Crash | C6: 41640 | D6: 42735 | E6: =AVERAGEIFS('Index Returns'!$B$2:$B$204,'Index Returns'!$A$2:$A$204,">="&$C6,'Index Returns'!$A$2:$A$204,"<="&$D6) | F6: =AVERAGEIFS('Index Returns'!$C$2:$C$204,'Index Returns'!$A$2:$A$204,">="&$C6,'Index Returns'!$A$2:$A$204,"<="&$D6) | G6: =AVERAGEIFS('Index Returns'!$D$2:$D$204,'Index Returns'!$A$2:$A$204,">="&$C6,'Index Returns'!$A$2:$A$204,"<="&$D6) | H6: =AVERAGEIFS('Index Returns'!$E$2:$E$204,'Index Returns'!$A$2:$A$204,">="&$C6,'Index Returns'!$A$2:$A$204,"<="&$D6) | I6: =AVERAGEIFS('Index Returns'!$F$2:$F$204,'Index Returns'!$A$2:$A$204,">="&$C6,'Index Returns'!$A$2:$A$204,"<="&$D6) | J6: =AVERAGEIFS('Index Returns'!$G$2:$G$204,'Index Returns'!$A$2:$A$204,">="&$C6,'Index Returns'!$A$2:$A$204,"<="&$D6) | L6: {=_xlfn.STDEV.S(IF(('Index Returns'!$A$2:$A$204>=$C6)*('Index Returns'!$A$2:$A$204<=$D6),'Index Returns'!$B$2:$B$204))} | M6: {=_xlfn.STDEV.S(IF(('Index Returns'!$A$2:$A$204>=$C6)*('Index Returns'!$A$2:$A$204<=$D6),'Index Returns'!$C$2:$C$204))} | N6: {=_xlfn.STDEV.S(IF(('Index Returns'!$A$2:$A$204>=$C6)*('Index Returns'!$A$2:$A$204<=$D6),'Index Returns'!$D$2:$D$204))} | O6: {=_xlfn.STDEV.S(IF(('Index Returns'!$A$2:$A$204>=$C6)*('Index Returns'!$A$2:$A$204<=$D6),'Index Returns'!$E$2:$E$204))} | P6: {=_xlfn.STDEV.S(IF(('Index Returns'!$A$2:$A$204>=$C6)*('Index Returns'!$A$2:$A$204<=$D6),'Index Returns'!$F$2:$F$204))} | Q6: {=_xlfn.STDEV.S(IF(('Index Returns'!$A$2:$A$204>=$C6)*('Index Returns'!$A$2:$A$204<=$D6),'Index Returns'!$G$2:$G$204))}
E8: Annual Return | L8: Annual Risk
A9: =A3 | B9: =B3 | C9: =C3 | D9: =D3 | E9: =(1+E3)^12-1 | F9: =(1+F3)^12-1 | G9: =(1+G3)^12-1 | H9: =(1+H3)^12-1 | I9: =(1+I3)^12-1 | J9: =(1+J3)^12-1 | L9: =L3*SQRT(12) | M9: =M3*SQRT(12) | N9: =N3*SQRT(12) | O9: =O3*SQRT(12) | P9: =P3*SQRT(12) | Q9: =Q3*SQRT(12)
A10: =A4 | B10: =B4 | C10: =C4 | D10: =D4 | E10: =(1+E4)^12-1 | F10: =(1+F4)^12-1 | G10: =(1+G4)^12-1 | H10: =(1+H4)^12-1 | I10: =(1+I4)^12-1 | J10: =(1+J4)^12-1 | L10: =L4*SQRT(12) | M10: =M4*SQRT(12) | N10: =N4*SQRT(12) | O10: =O4*SQRT(12) | P10: =P4*SQRT(12) | Q10: =Q4*SQRT(12)
A11: =A5 | B11: =B5 | C11: =C5 | D11: =D5 | E11: =(1+E5)^12-1 | F11: =(1+F5)^12-1 | G11: =(1+G5)^12-1 | H11: =(1+H5)^12-1 | I11: =(1+I5)^12-1 | J11: =(1+J5)^12-1 | L11: =L5*SQRT(12) | M11: =M5*SQRT(12) | N11: =N5*SQRT(12) | O11: =O5*SQRT(12) | P11: =P5*SQRT(12) | Q11: =Q5*SQRT(12)
A12: commodity price shock | B12: Oil Price Crash | C12: 41640 | D12: 42735 | E12: =(1+E6)^12-1 | F12: =(1+F6)^12-1 | G12: =(1+G6)^12-1 | H12: =(1+H6)^12-1 | I12: =(1+I6)^12-1 | J12: =(1+J6)^12-1 | L12: =L6*SQRT(12) | M12: =M6*SQRT(12) | N12: =N6*SQRT(12) | O12: =O6*SQRT(12) | P12: =P6*SQRT(12) | Q12: =Q6*SQRT(12)

Sheet Sensitivity Analysis
A1: Scenario-based sensitivity analysis - Commodity price shock (Oil Price Crash, Jan-2014 to Dec-2016)
A2: Method: replace the CME inputs with the annualised return and risk each asset actually delivered during the scenario window, keep the SAA weights and CME correlations, and re-measure the portfolio.
A3: Risk-free rate | B3: ='MC Sim - Oil Price Crash'!T6
A5: A. Asset-level impact of the oil price shock
A6: Asset | B6: SAA weight | C6: CME return | D6: Oil shock return | E6: Change | F6: Contribution to portfolio return change | G6: CME vol | H6: Oil shock vol | I6: Change
A7: ='SAA with CME'!C16 | B7: ='SAA with CME'!C17 | C7: ='SAA with CME'!C11 | D7: ='Scenarios MPT'!E12 | E7: =D7-C7 | F7: =B7*E7 | G7: ='SAA with CME'!C12 | H7: ='Scenarios MPT'!L12 | I7: =H7-G7
A8: ='SAA with CME'!D16 | B8: ='SAA with CME'!D17 | C8: ='SAA with CME'!D11 | D8: ='Scenarios MPT'!F12 | E8: =D8-C8 | F8: =B8*E8 | G8: ='SAA with CME'!D12 | H8: ='Scenarios MPT'!M12 | I8: =H8-G8
A9: ='SAA with CME'!E16 | B9: ='SAA with CME'!E17 | C9: ='SAA with CME'!E11 | D9: ='Scenarios MPT'!G12 | E9: =D9-C9 | F9: =B9*E9 | G9: ='SAA with CME'!E12 | H9: ='Scenarios MPT'!N12 | I9: =H9-G9
A10: ='SAA with CME'!F16 | B10: ='SAA with CME'!F17 | C10: ='SAA with CME'!F11 | D10: ='Scenarios MPT'!H12 | E10: =D10-C10 | F10: =B10*E10 | G10: ='SAA with CME'!F12 | H10: ='Scenarios MPT'!O12 | I10: =H10-G10
A11: ='SAA with CME'!G16 | B11: ='SAA with CME'!G17 | C11: ='SAA with CME'!G11 | D11: ='Scenarios MPT'!I12 | E11: =D11-C11 | F11: =B11*E11 | G11: ='SAA with CME'!G12 | H11: ='Scenarios MPT'!P12 | I11: =H11-G11
A12: ='SAA with CME'!H16 | B12: ='SAA with CME'!H17 | C12: ='SAA with CME'!H11 | D12: ='Scenarios MPT'!J12 | E12: =D12-C12 | F12: =B12*E12 | G12: ='SAA with CME'!H12 | H12: ='Scenarios MPT'!Q12 | I12: =H12-G12
A13: Total / Portfolio | B13: =SUM(B7:B12) | F13: =SUM(F7:F12)
A16: B. Portfolio under each scenario (SAA weights, CME correlations)
A17: Metric | B17: Base case (CME) | C17: Dot-Com Bubble Burst | D17: Global Financial Crisis | E17: European Debt Crisis | F17: Oil Price Crash
A18: Expected annual return | B18: ='SAA with CME'!I18 | C18: =SUMPRODUCT('SAA with CME'!$C$17:$H$17,'Scenarios MPT'!$E$9:$J$9) | D18: =SUMPRODUCT('SAA with CME'!$C$17:$H$17,'Scenarios MPT'!$E$10:$J$10) | E18: =SUMPRODUCT('SAA with CME'!$C$17:$H$17,'Scenarios MPT'!$E$11:$J$11) | F18: =SUMPRODUCT('SAA with CME'!$C$17:$H$17,'Scenarios MPT'!$E$12:$J$12)
A19: Expected annual volatility | B19: ='SAA with CME'!I20 | C19: {=SQRT(MMULT(MMULT('SAA with CME'!$C$17:$H$17*'Scenarios MPT'!$L$9:$Q$9,'SAA with CME'!$C$4:$H$9),TRANSPOSE('SAA with CME'!$C$17:$H$17*'Scenarios MPT'!$L$9:$Q$9)))} | D19: {=SQRT(MMULT(MMULT('SAA with CME'!$C$17:$H$17*'Scenarios MPT'!$L$10:$Q$10,'SAA with CME'!$C$4:$H$9),TRANSPOSE('SAA with CME'!$C$17:$H$17*'Scenarios MPT'!$L$10:$Q$10)))} | E19: {=SQRT(MMULT(MMULT('SAA with CME'!$C$17:$H$17*'Scenarios MPT'!$L$11:$Q$11,'SAA with CME'!$C$4:$H$9),TRANSPOSE('SAA with CME'!$C$17:$H$17*'Scenarios MPT'!$L$11:$Q$11)))} | F19: {=SQRT(MMULT(MMULT('SAA with CME'!$C$17:$H$17*'Scenarios MPT'!$L$12:$Q$12,'SAA with CME'!$C$4:$H$9),TRANSPOSE('SAA with CME'!$C$17:$H$17*'Scenarios MPT'!$L$12:$Q$12)))}
A20: Sharpe ratio | B20: =(B18-$B$3)/B19 | C20: =(C18-$B$3)/C19 | D20: =(D18-$B$3)/D19 | E20: =(E18-$B$3)/E19 | F20: =(F18-$B$3)/F19
A21: Return vs. base case | B21: =B18-$B$18 | C21: =C18-$B$18 | D21: =D18-$B$18 | E21: =E18-$B$18 | F21: =F18-$B$18
A22: Volatility vs. base case | B22: =B19-$B$19 | C22: =C19-$B$19 | D22: =D19-$B$19 | E22: =E19-$B$19 | F22: =F19-$B$19
A23: 1-year 95% VaR (parametric) | B23: =B18-1.645*B19 | C23: =C18-1.645*C19 | D23: =D18-1.645*D19 | E23: =E18-1.645*E19 | F23: =F18-1.645*F19
A26: C. Sensitivity to the severity of the commodity shock
A27: Shock severity (x Oil Price Crash move) | B27: 0 | C27: 0.5 | D27: 1 | E27: 1.5 | F27: 2
A28: Portfolio expected annual return | B28: =$B$18+B27*$F$13 | C28: =$B$18+C27*$F$13 | D28: =$B$18+D27*$F$13 | E28: =$B$18+E27*$F$13 | F28: =$B$18+F27*$F$13
A29: Change vs. base case | B29: =B28-$B$18 | C29: =C28-$B$18 | D29: =D28-$B$18 | E29: =E28-$B$18 | F29: =F28-$B$18
A30: Each asset's return is moved linearly from its CME value by the multiple of its Oil Price Crash change (1.0x = the historical shock).

Sheet MC Sim - Oil Price Crash
B1: US Large Cap | C1: Dev ex US | D1: EM | E1: UST | F1: US IG Corp Bond | G1: REITs | I1: SAA weights: | J1: ='SAA with CME'!C17 | K1: ='SAA with CME'!D17 | L1: ='SAA with CME'!E17 | M1: ='SAA with CME'!F17 | N1: ='SAA with CME'!G17 | O1: ='SAA with CME'!H17 | Q1: Monthly Portfolio Return | S1: Compounded Annual Portfolio Return | T1: {=GEOMEAN(Q2:Q37+1)^12-1} | W1: Average Annual Return | X1: Annual Volatility of the Portfolio
A2: 41670 | B2: =NORMINV(RAND(),'Scenarios MPT'!E$6,'Scenarios MPT'!L$6) | C2: =NORMINV(RAND(),'Scenarios MPT'!F$6,'Scenarios MPT'!M$6) | D2: =NORMINV(RAND(),'Scenarios MPT'!G$6,'Scenarios MPT'!N$6) | E2: =NORMINV(RAND(),'Scenarios MPT'!H$6,'Scenarios MPT'!O$6) | F2: =NORMINV(RAND(),'Scenarios MPT'!I$6,'Scenarios MPT'!P$6) | G2: =NORMINV(RAND(),'Scenarios MPT'!J$6,'Scenarios MPT'!Q$6) | J2: =J$1*B2 | K2: =K$1*C2 | L2: =L$1*D2 | M2: =M$1*E2 | N2: =N$1*F2 | O2: =O$1*G2 | Q2: =SUM(J2:O2) | S2: Average Monthly Return | T2: =AVERAGE(Q2:Q37) | W2: 0.047359861 | X2: 0.05081973
A3: 41698 | B3: =NORMINV(RAND(),'Scenarios MPT'!E$6,'Scenarios MPT'!L$6) | C3: =NORMINV(RAND(),'Scenarios MPT'!F$6,'Scenarios MPT'!M$6) | D3: =NORMINV(RAND(),'Scenarios MPT'!G$6,'Scenarios MPT'!N$6) | E3: =NORMINV(RAND(),'Scenarios MPT'!H$6,'Scenarios MPT'!O$6) | F3: =NORMINV(RAND(),'Scenarios MPT'!I$6,'Scenarios MPT'!P$6) | G3: =NORMINV(RAND(),'Scenarios MPT'!J$6,'Scenarios MPT'!Q$6) | J3: =J$1*B3 | K3: =K$1*C3 | L3: =L$1*D3 | M3: =M$1*E3 | N3: =N$1*F3 | O3: =O$1*G3 | Q3: =SUM(J3:O3) | S3: Average Annual Return | T3: =(1+T2)^12-1 | W3: 0.074022494 | X3: 0.05536921
A4: 41729 | B4: =NORMINV(RAND(),'Scenarios MPT'!E$6,'Scenarios MPT'!L$6) | C4: =NORMINV(RAND(),'Scenarios MPT'!F$6,'Scenarios MPT'!M$6) | D4: =NORMINV(RAND(),'Scenarios MPT'!G$6,'Scenarios MPT'!N$6) | E4: =NORMINV(RAND(),'Scenarios MPT'!H$6,'Scenarios MPT'!O$6) | F4: =NORMINV(RAND(),'Scenarios MPT'!I$6,'Scenarios MPT'!P$6) | G4: =NORMINV(RAND(),'Scenarios MPT'!J$6,'Scenarios MPT'!Q$6) | J4: =J$1*B4 | K4: =K$1*C4 | L4: =L$1*D4 | M4: =M$1*E4 | N4: =N$1*F4 | O4: =O$1*G4 | Q4: =SUM(J4:O4) | S4: Volatility of Portfolio | T4: =_xlfn.STDEV.S(Q2:Q37) | W4: -0.033590476 | X4: 0.052697925
A5: 41759 | B5: =NORMINV(RAND(),'Scenarios MPT'!E$6,'Scenarios MPT'!L$6) | C5: =NORMINV(RAND(),'Scenarios MPT'!F$6,'Scenarios MPT'!M$6) | D5: =NORMINV(RAND(),'Scenarios MPT'!G$6,'Scenarios MPT'!N$6) | E5: =NORMINV(RAND(),'Scenarios MPT'!H$6,'Scenarios MPT'!O$6) | F5: =NORMINV(RAND(),'Scenarios MPT'!I$6,'Scenarios MPT'!P$6) | G5: =NORMINV(RAND(),'Scenarios MPT'!J$6,'Scenarios MPT'!Q$6) | J5: =J$1*B5 | K5: =K$1*C5 | L5: =L$1*D5 | M5: =M$1*E5 | N5: =N$1*F5 | O5: =O$1*G5 | Q5: =SUM(J5:O5) | S5: Annual Volatility of the Portfolio | T5: =T4*SQRT(12) | W5: 0.01967726 | X5: 0.052086368
A6: 41789 | B6: =NORMINV(RAND(),'Scenarios MPT'!E$6,'Scenarios MPT'!L$6) | C6: =NORMINV(RAND(),'Scenarios MPT'!F$6,'Scenarios MPT'!M$6) | D6: =NORMINV(RAND(),'Scenarios MPT'!G$6,'Scenarios MPT'!N$6) | E6: =NORMINV(RAND(),'Scenarios MPT'!H$6,'Scenarios MPT'!O$6) | F6: =NORMINV(RAND(),'Scenarios MPT'!I$6,'Scenarios MPT'!P$6) | G6: =NORMINV(RAND(),'Scenarios MPT'!J$6,'Scenarios MPT'!Q$6) | J6: =J$1*B6 | K6: =K$1*C6 | L6: =L$1*D6 | M6: =M$1*E6 | N6: =N$1*F6 | O6: =O$1*G6 | Q6: =SUM(J6:O6) | S6: Risk-Free Rate | T6: 0.0165 | W6: 0.034785003 | X6: 0.057177502
A7: 41820 | B7: =NORMINV(RAND(),'Scenarios MPT'!E$6,'Scenarios MPT'!L$6) | C7: =NORMINV(RAND(),'Scenarios MPT'!F$6,'Scenarios MPT'!M$6) | D7: =NORMINV(RAND(),'Scenarios MPT'!G$6,'Scenarios MPT'!N$6) | E7: =NORMINV(RAND(),'Scenarios MPT'!H$6,'Scenarios MPT'!O$6) | F7: =NORMINV(RAND(),'Scenarios MPT'!I$6,'Scenarios MPT'!P$6) | G7: =NORMINV(RAND(),'Scenarios MPT'!J$6,'Scenarios MPT'!Q$6) | J7: =J$1*B7 | K7: =K$1*C7 | L7: =L$1*D7 | M7: =M$1*E7 | N7: =N$1*F7 | O7: =O$1*G7 | Q7: =SUM(J7:O7) | S7: Sharpe Ratio | T7: =(T3-T6)/T5 | W7: 0.035812056 | X7: 0.041853299
A8: 41851 | B8: =NORMINV(RAND(),'Scenarios MPT'!E$6,'Scenarios MPT'!L$6) | C8: =NORMINV(RAND(),'Scenarios MPT'!F$6,'Scenarios MPT'!M$6) | D8: =NORMINV(RAND(),'Scenarios MPT'!G$6,'Scenarios MPT'!N$6) | E8: =NORMINV(RAND(),'Scenarios MPT'!H$6,'Scenarios MPT'!O$6) | F8: =NORMINV(RAND(),'Scenarios MPT'!I$6,'Scenarios MPT'!P$6) | G8: =NORMINV(RAND(),'Scenarios MPT'!J$6,'Scenarios MPT'!Q$6) | J8: =J$1*B8 | K8: =K$1*C8 | L8: =L$1*D8 | M8: =M$1*E8 | N8: =N$1*F8 | O8: =O$1*G8 | Q8: =SUM(J8:O8) | W8: 0.079660167 | X8: 0.036643893
A9: 41880 | B9: =NORMINV(RAND(),'Scenarios MPT'!E$6,'Scenarios MPT'!L$6) | C9: =NORMINV(RAND(),'Scenarios MPT'!F$6,'Scenarios MPT'!M$6) | D9: =NORMINV(RAND(),'Scenarios MPT'!G$6,'Scenarios MPT'!N$6) | E9: =NORMINV(RAND(),'Scenarios MPT'!H$6,'Scenarios MPT'!O$6) | F9: =NORMINV(RAND(),'Scenarios MPT'!I$6,'Scenarios MPT'!P$6) | G9: =NORMINV(RAND(),'Scenarios MPT'!J$6,'Scenarios MPT'!Q$6) | J9: =J$1*B9 | K9: =K$1*C9 | L9: =L$1*D9 | M9: =M$1*E9 | N9: =N$1*F9 | O9: =O$1*G9 | Q9: =SUM(J9:O9) | S9: Simulation Average Annual Return | T9: =AVERAGE(W2:W10001) | W9: 0.04855166 | X9: 0.057817946
A10: 41912 | B10: =NORMINV(RAND(),'Scenarios MPT'!E$6,'Scenarios MPT'!L$6) | C10: =NORMINV(RAND(),'Scenarios MPT'!F$6,'Scenarios MPT'!M$6) | D10: =NORMINV(RAND(),'Scenarios MPT'!G$6,'Scenarios MPT'!N$6) | E10: =NORMINV(RAND(),'Scenarios MPT'!H$6,'Scenarios MPT'!O$6) | F10: =NORMINV(RAND(),'Scenarios MPT'!I$6,'Scenarios MPT'!P$6) | G10: =NORMINV(RAND(),'Scenarios MPT'!J$6,'Scenarios MPT'!Q$6) | J10: =J$1*B10 | K10: =K$1*C10 | L10: =L$1*D10 | M10: =M$1*E10 | N10: =N$1*F10 | O10: =O$1*G10 | Q10: =SUM(J10:O10) | S10: Simulation Average Annual Volatility | T10: =AVERAGE(X2:X10001) | W10: 0.034932372 | X10: 0.05097497
A11: 41943 | B11: =NORMINV(RAND(),'Scenarios MPT'!E$6,'Scenarios MPT'!L$6) | C11: =NORMINV(RAND(),'Scenarios MPT'!F$6,'Scenarios MPT'!M$6) | D11: =NORMINV(RAND(),'Scenarios MPT'!G$6,'Scenarios MPT'!N$6) | E11: =NORMINV(RAND(),'Scenarios MPT'!H$6,'Scenarios MPT'!O$6) | F11: =NORMINV(RAND(),'Scenarios MPT'!I$6,'Scenarios MPT'!P$6) | G11: =NORMINV(RAND(),'Scenarios MPT'!J$6,'Scenarios MPT'!Q$6) | J11: =J$1*B11 | K11: =K$1*C11 | L11: =L$1*D11 | M11: =M$1*E11 | N11: =N$1*F11 | O11: =O$1*G11 | Q11: =SUM(J11:O11) | W11: 0.017966067 | X11: 0.061033298
A12: 41971 | B12: =NORMINV(RAND(),'Scenarios MPT'!E$6,'Scenarios MPT'!L$6) | C12: =NORMINV(RAND(),'Scenarios MPT'!F$6,'Scenarios MPT'!M$6) | D12: =NORMINV(RAND(),'Scenarios MPT'!G$6,'Scenarios MPT'!N$6) | E12: =NORMINV(RAND(),'Scenarios MPT'!H$6,'Scenarios MPT'!O$6) | F12: =NORMINV(RAND(),'Scenarios MPT'!I$6,'Scenarios MPT'!P$6) | G12: =NORMINV(RAND(),'Scenarios MPT'!J$6,'Scenarios MPT'!Q$6) | J12: =J$1*B12 | K12: =K$1*C12 | L12: =L$1*D12 | M12: =M$1*E12 | N12: =N$1*F12 | O12: =O$1*G12 | Q12: =SUM(J12:O12) | S12: Columns B:G draw a new random path on every recalculation (F9). | W12: -0.0019830499 | X12: 0.056620422
A13: 42004 | B13: =NORMINV(RAND(),'Scenarios MPT'!E$6,'Scenarios MPT'!L$6) | C13: =NORMINV(RAND(),'Scenarios MPT'!F$6,'Scenarios MPT'!M$6) | D13: =NORMINV(RAND(),'Scenarios MPT'!G$6,'Scenarios MPT'!N$6) | E13: =NORMINV(RAND(),'Scenarios MPT'!H$6,'Scenarios MPT'!O$6) | F13: =NORMINV(RAND(),'Scenarios MPT'!I$6,'Scenarios MPT'!P$6) | G13: =NORMINV(RAND(),'Scenarios MPT'!J$6,'Scenarios MPT'!Q$6) | J13: =J$1*B13 | K13: =K$1*C13 | L13: =L$1*D13 | M13: =M$1*E13 | N13: =N$1*F13 | O13: =O$1*G13 | Q13: =SUM(J13:O13) | S13: W:X hold the stored results of 10,000 simulation runs (T3 and T5 after each recalculation), | W13: -0.025456903 | X13: 0.053294835
A14: 42034 | B14: =NORMINV(RAND(),'Scenarios MPT'!E$6,'Scenarios MPT'!L$6) | C14: =NORMINV(RAND(),'Scenarios MPT'!F$6,'Scenarios MPT'!M$6) | D14: =NORMINV(RAND(),'Scenarios MPT'!G$6,'Scenarios MPT'!N$6) | E14: =NORMINV(RAND(),'Scenarios MPT'!H$6,'Scenarios MPT'!O$6) | F14: =NORMINV(RAND(),'Scenarios MPT'!I$6,'Scenarios MPT'!P$6) | G14: =NORMINV(RAND(),'Scenarios MPT'!J$6,'Scenarios MPT'!Q$6) | J14: =J$1*B14 | K14: =K$1*C14 | L14: =L$1*D14 | M14: =M$1*E14 | N14: =N$1*F14 | O14: =O$1*G14 | Q14: =SUM(J14:O14) | S14: i.e. the output of the RecalculateAndStore macro (see the MC Summary sheet). | W14: 0.043862068 | X14: 0.058729279
A15: 42062 | B15: =NORMINV(RAND(),'Scenarios MPT'!E$6,'Scenarios MPT'!L$6) | C15: =NORMINV(RAND(),'Scenarios MPT'!F$6,'Scenarios MPT'!M$6) | D15: =NORMINV(RAND(),'Scenarios MPT'!G$6,'Scenarios MPT'!N$6) | E15: =NORMINV(RAND(),'Scenarios MPT'!H$6,'Scenarios MPT'!O$6) | F15: =NORMINV(RAND(),'Scenarios MPT'!I$6,'Scenarios MPT'!P$6) | G15: =NORMINV(RAND(),'Scenarios MPT'!J$6,'Scenarios MPT'!Q$6) | J15: =J$1*B15 | K15: =K$1*C15 | L15: =L$1*D15 | M15: =M$1*E15 | N15: =N$1*F15 | O15: =O$1*G15 | Q15: =SUM(J15:O15) | W15: 0.016493808 | X15: 0.051778162
A16: 42094 | B16: =NORMINV(RAND(),'Scenarios MPT'!E$6,'Scenarios MPT'!L$6) | C16: =NORMINV(RAND(),'Scenarios MPT'!F$6,'Scenarios MPT'!M$6) | D16: =NORMINV(RAND(),'Scenarios MPT'!G$6,'Scenarios MPT'!N$6) | E16: =NORMINV(RAND(),'Scenarios MPT'!H$6,'Scenarios MPT'!O$6) | F16: =NORMINV(RAND(),'Scenarios MPT'!I$6,'Scenarios MPT'!P$6) | G16: =NORMINV(RAND(),'Scenarios MPT'!J$6,'Scenarios MPT'!Q$6) | J16: =J$1*B16 | K16: =K$1*C16 | L16: =L$1*D16 | M16: =M$1*E16 | N16: =N$1*F16 | O16: =O$1*G16 | Q16: =SUM(J16:O16) | W16: -0.013602675 | X16: 0.051489808
A17: 42124 | B17: =NORMINV(RAND(),'Scenarios MPT'!E$6,'Scenarios MPT'!L$6) | C17: =NORMINV(RAND(),'Scenarios MPT'!F$6,'Scenarios MPT'!M$6) | D17: =NORMINV(RAND(),'Scenarios MPT'!G$6,'Scenarios MPT'!N$6) | E17: =NORMINV(RAND(),'Scenarios MPT'!H$6,'Scenarios MPT'!O$6) | F17: =NORMINV(RAND(),'Scenarios MPT'!I$6,'Scenarios MPT'!P$6) | G17: =NORMINV(RAND(),'Scenarios MPT'!J$6,'Scenarios MPT'!Q$6) | J17: =J$1*B17 | K17: =K$1*C17 | L17: =L$1*D17 | M17: =M$1*E17 | N17: =N$1*F17 | O17: =O$1*G17 | Q17: =SUM(J17:O17) | W17: 0.063679418 | X17: 0.049969121
A18: 42153 | B18: =NORMINV(RAND(),'Scenarios MPT'!E$6,'Scenarios MPT'!L$6) | C18: =NORMINV(RAND(),'Scenarios MPT'!F$6,'Scenarios MPT'!M$6) | D18: =NORMINV(RAND(),'Scenarios MPT'!G$6,'Scenarios MPT'!N$6) | E18: =NORMINV(RAND(),'Scenarios MPT'!H$6,'Scenarios MPT'!O$6) | F18: =NORMINV(RAND(),'Scenarios MPT'!I$6,'Scenarios MPT'!P$6) | G18: =NORMINV(RAND(),'Scenarios MPT'!J$6,'Scenarios MPT'!Q$6) | J18: =J$1*B18 | K18: =K$1*C18 | L18: =L$1*D18 | M18: =M$1*E18 | N18: =N$1*F18 | O18: =O$1*G18 | Q18: =SUM(J18:O18) | W18: 0.034534796 | X18: 0.055422286
A19: 42185 | B19: =NORMINV(RAND(),'Scenarios MPT'!E$6,'Scenarios MPT'!L$6) | C19: =NORMINV(RAND(),'Scenarios MPT'!F$6,'Scenarios MPT'!M$6) | D19: =NORMINV(RAND(),'Scenarios MPT'!G$6,'Scenarios MPT'!N$6) | E19: =NORMINV(RAND(),'Scenarios MPT'!H$6,'Scenarios MPT'!O$6) | F19: =NORMINV(RAND(),'Scenarios MPT'!I$6,'Scenarios MPT'!P$6) | G19: =NORMINV(RAND(),'Scenarios MPT'!J$6,'Scenarios MPT'!Q$6) | J19: =J$1*B19 | K19: =K$1*C19 | L19: =L$1*D19 | M19: =M$1*E19 | N19: =N$1*F19 | O19: =O$1*G19 | Q19: =SUM(J19:O19) | W19: 0.05687369 | X19: 0.047014165
A20: 42216 | B20: =NORMINV(RAND(),'Scenarios MPT'!E$6,'Scenarios MPT'!L$6) | C20: =NORMINV(RAND(),'Scenarios MPT'!F$6,'Scenarios MPT'!M$6) | D20: =NORMINV(RAND(),'Scenarios MPT'!G$6,'Scenarios MPT'!N$6) | E20: =NORMINV(RAND(),'Scenarios MPT'!H$6,'Scenarios MPT'!O$6) | F20: =NORMINV(RAND(),'Scenarios MPT'!I$6,'Scenarios MPT'!P$6) | G20: =NORMINV(RAND(),'Scenarios MPT'!J$6,'Scenarios MPT'!Q$6) | J20: =J$1*B20 | K20: =K$1*C20 | L20: =L$1*D20 | M20: =M$1*E20 | N20: =N$1*F20 | O20: =O$1*G20 | Q20: =SUM(J20:O20) | W20: -0.015391209 | X20: 0.055663579
A21: 42247 | B21: =NORMINV(RAND(),'Scenarios MPT'!E$6,'Scenarios MPT'!L$6) | C21: =NORMINV(RAND(),'Scenarios MPT'!F$6,'Scenarios MPT'!M$6) | D21: =NORMINV(RAND(),'Scenarios MPT'!G$6,'Scenarios MPT'!N$6) | E21: =NORMINV(RAND(),'Scenarios MPT'!H$6,'Scenarios MPT'!O$6) | F21: =NORMINV(RAND(),'Scenarios MPT'!I$6,'Scenarios MPT'!P$6) | G21: =NORMINV(RAND(),'Scenarios MPT'!J$6,'Scenarios MPT'!Q$6) | J21: =J$1*B21 | K21: =K$1*C21 | L21: =L$1*D21 | M21: =M$1*E21 | N21: =N$1*F21 | O21: =O$1*G21 | Q21: =SUM(J21:O21) | W21: 0.0048807798 | X21: 0.05315822
A22: 42277 | B22: =NORMINV(RAND(),'Scenarios MPT'!E$6,'Scenarios MPT'!L$6) | C22: =NORMINV(RAND(),'Scenarios MPT'!F$6,'Scenarios MPT'!M$6) | D22: =NORMINV(RAND(),'Scenarios MPT'!G$6,'Scenarios MPT'!N$6) | E22: =NORMINV(RAND(),'Scenarios MPT'!H$6,'Scenarios MPT'!O$6) | F22: =NORMINV(RAND(),'Scenarios MPT'!I$6,'Scenarios MPT'!P$6) | G22: =NORMINV(RAND(),'Scenarios MPT'!J$6,'Scenarios MPT'!Q$6) | J22: =J$1*B22 | K22: =K$1*C22 | L22: =L$1*D22 | M22: =M$1*E22 | N22: =N$1*F22 | O22: =O$1*G22 | Q22: =SUM(J22:O22) | W22: 0.04230383 | X22: 0.051894571
A23: 42307 | B23: =NORMINV(RAND(),'Scenarios MPT'!E$6,'Scenarios MPT'!L$6) | C23: =NORMINV(RAND(),'Scenarios MPT'!F$6,'Scenarios MPT'!M$6) | D23: =NORMINV(RAND(),'Scenarios MPT'!G$6,'Scenarios MPT'!N$6) | E23: =NORMINV(RAND(),'Scenarios MPT'!H$6,'Scenarios MPT'!O$6) | F23: =NORMINV(RAND(),'Scenarios MPT'!I$6,'Scenarios MPT'!P$6) | G23: =NORMINV(RAND(),'Scenarios MPT'!J$6,'Scenarios MPT'!Q$6) | J23: =J$1*B23 | K23: =K$1*C23 | L23: =L$1*D23 | M23: =M$1*E23 | N23: =N$1*F23 | O23: =O$1*G23 | Q23: =SUM(J23:O23) | W23: -0.01647337 | X23: 0.054913103
A24: 42338 | B24: =NORMINV(RAND(),'Scenarios MPT'!E$6,'Scenarios MPT'!L$6) | C24: =NORMINV(RAND(),'Scenarios MPT'!F$6,'Scenarios MPT'!M$6) | D24: =NORMINV(RAND(),'Scenarios MPT'!G$6,'Scenarios MPT'!N$6) | E24: =NORMINV(RAND(),'Scenarios MPT'!H$6,'Scenarios MPT'!O$6) | F24: =NORMINV(RAND(),'Scenarios MPT'!I$6,'Scenarios MPT'!P$6) | G24: =NORMINV(RAND(),'Scenarios MPT'!J$6,'Scenarios MPT'!Q$6) | J24: =J$1*B24 | K24: =K$1*C24 | L24: =L$1*D24 | M24: =M$1*E24 | N24: =N$1*F24 | O24: =O$1*G24 | Q24: =SUM(J24:O24) | W24: -0.0053074551 | X24: 0.04140108
A25: 42369 | B25: =NORMINV(RAND(),'Scenarios MPT'!E$6,'Scenarios MPT'!L$6) | C25: =NORMINV(RAND(),'Scenarios MPT'!F$6,'Scenarios MPT'!M$6) | D25: =NORMINV(RAND(),'Scenarios MPT'!G$6,'Scenarios MPT'!N$6) | E25: =NORMINV(RAND(),'Scenarios MPT'!H$6,'Scenarios MPT'!O$6) | F25: =NORMINV(RAND(),'Scenarios MPT'!I$6,'Scenarios MPT'!P$6) | G25: =NORMINV(RAND(),'Scenarios MPT'!J$6,'Scenarios MPT'!Q$6) | J25: =J$1*B25 | K25: =K$1*C25 | L25: =L$1*D25 | M25: =M$1*E25 | N25: =N$1*F25 | O25: =O$1*G25 | Q25: =SUM(J25:O25) | W25: -0.039152833 | X25: 0.046772281
A26: 42398 | B26: =NORMINV(RAND(),'Scenarios MPT'!E$6,'Scenarios MPT'!L$6) | C26: =NORMINV(RAND(),'Scenarios MPT'!F$6,'Scenarios MPT'!M$6) | D26: =NORMINV(RAND(),'Scenarios MPT'!G$6,'Scenarios MPT'!N$6) | E26: =NORMINV(RAND(),'Scenarios MPT'!H$6,'Scenarios MPT'!O$6) | F26: =NORMINV(RAND(),'Scenarios MPT'!I$6,'Scenarios MPT'!P$6) | G26: =NORMINV(RAND(),'Scenarios MPT'!J$6,'Scenarios MPT'!Q$6) | J26: =J$1*B26 | K26: =K$1*C26 | L26: =L$1*D26 | M26: =M$1*E26 | N26: =N$1*F26 | O26: =O$1*G26 | Q26: =SUM(J26:O26) | W26: 0.0083828752 | X26: 0.049727628
... A37: 42734 | B37: =NORMINV(RAND(),'Scenarios MPT'!E$6,'Scenarios MPT'!L$6) | C37: =NORMINV(RAND(),'Scenarios MPT'!F$6,'Scenarios MPT'!M$6) | D37: =NORMINV(RAND(),'Scenarios MPT'!G$6,'Scenarios MPT'!N$6) | E37: =NORMINV(RAND(),'Scenarios MPT'!H$6,'Scenarios MPT'!O$6) | F37: =NORMINV(RAND(),'Scenarios MPT'!I$6,'Scenarios MPT'!P$6) | G37: =NORMINV(RAND(),'Scenarios MPT'!J$6,'Scenarios MPT'!Q$6) | J37: =J$1*B37 | K37: =K$1*C37 | L37: =L$1*D37 | M37: =M$1*E37 | N37: =N$1*F37 | O37: =O$1*G37 | Q37: =SUM(J37:O37) | W37: 0.024950023 | X37: 0.043478552
W38: -0.010820892 | X38: 0.054034482
W39: -0.011645932 | X39: 0.049031773
W40: 0.014611938 | X40: 0.058521656
W41: -0.0077742677 | X41: 0.048120909
W42: 0.009238872 | X42: 0.056655791
W43: -0.047534953 | X43: 0.049135771
W44: 0.042048946 | X44: 0.058143926
W45: 0.043740325 | X45: 0.054177831
W46: 0.028344723 | X46: 0.050631021
W47: -0.023693947 | X47: 0.052476505
W48: 0.091541158 | X48: 0.055840813
W49: 0.013327138 | X49: 0.044343974
... W10001: 0.0505309 | X10001: 0.047235841

Sheet MC Sim - Dot Com Bubble Burst
B1: US Large Cap | C1: Dev ex US | D1: EM | E1: UST | F1: US IG Corp Bond | G1: REITs | I1: SAA weights: | J1: ='SAA with CME'!C17 | K1: ='SAA with CME'!D17 | L1: ='SAA with CME'!E17 | M1: ='SAA with CME'!F17 | N1: ='SAA with CME'!G17 | O1: ='SAA with CME'!H17 | Q1: Monthly Portfolio Return | S1: Compounded Annual Portfolio Return | T1: {=GEOMEAN(Q2:Q37+1)^12-1} | W1: Average Annual Return | X1: Annual Volatility of the Portfolio
A2: 36556 | B2: =NORMINV(RAND(),'Scenarios MPT'!E$3,'Scenarios MPT'!L$3) | C2: =NORMINV(RAND(),'Scenarios MPT'!F$3,'Scenarios MPT'!M$3) | D2: =NORMINV(RAND(),'Scenarios MPT'!G$3,'Scenarios MPT'!N$3) | E2: =NORMINV(RAND(),'Scenarios MPT'!H$3,'Scenarios MPT'!O$3) | F2: =NORMINV(RAND(),'Scenarios MPT'!I$3,'Scenarios MPT'!P$3) | G2: =NORMINV(RAND(),'Scenarios MPT'!J$3,'Scenarios MPT'!Q$3) | J2: =J$1*B2 | K2: =K$1*C2 | L2: =L$1*D2 | M2: =M$1*E2 | N2: =N$1*F2 | O2: =O$1*G2 | Q2: =SUM(J2:O2) | S2: Average Monthly Return | T2: =AVERAGE(Q2:Q37) | W2: -0.070395374 | X2: 0.073806977
A3: 36584 | B3: =NORMINV(RAND(),'Scenarios MPT'!E$3,'Scenarios MPT'!L$3) | C3: =NORMINV(RAND(),'Scenarios MPT'!F$3,'Scenarios MPT'!M$3) | D3: =NORMINV(RAND(),'Scenarios MPT'!G$3,'Scenarios MPT'!N$3) | E3: =NORMINV(RAND(),'Scenarios MPT'!H$3,'Scenarios MPT'!O$3) | F3: =NORMINV(RAND(),'Scenarios MPT'!I$3,'Scenarios MPT'!P$3) | G3: =NORMINV(RAND(),'Scenarios MPT'!J$3,'Scenarios MPT'!Q$3) | J3: =J$1*B3 | K3: =K$1*C3 | L3: =L$1*D3 | M3: =M$1*E3 | N3: =N$1*F3 | O3: =O$1*G3 | Q3: =SUM(J3:O3) | S3: Average Annual Return | T3: =(1+T2)^12-1 | W3: -0.086177768 | X3: 0.066776299
A4: 36615 | B4: =NORMINV(RAND(),'Scenarios MPT'!E$3,'Scenarios MPT'!L$3) | C4: =NORMINV(RAND(),'Scenarios MPT'!F$3,'Scenarios MPT'!M$3) | D4: =NORMINV(RAND(),'Scenarios MPT'!G$3,'Scenarios MPT'!N$3) | E4: =NORMINV(RAND(),'Scenarios MPT'!H$3,'Scenarios MPT'!O$3) | F4: =NORMINV(RAND(),'Scenarios MPT'!I$3,'Scenarios MPT'!P$3) | G4: =NORMINV(RAND(),'Scenarios MPT'!J$3,'Scenarios MPT'!Q$3) | J4: =J$1*B4 | K4: =K$1*C4 | L4: =L$1*D4 | M4: =M$1*E4 | N4: =N$1*F4 | O4: =O$1*G4 | Q4: =SUM(J4:O4) | S4: Volatility of Portfolio | T4: =_xlfn.STDEV.S(Q2:Q37) | W4: -0.082201506 | X4: 0.067025571
A5: 36645 | B5: =NORMINV(RAND(),'Scenarios MPT'!E$3,'Scenarios MPT'!L$3) | C5: =NORMINV(RAND(),'Scenarios MPT'!F$3,'Scenarios MPT'!M$3) | D5: =NORMINV(RAND(),'Scenarios MPT'!G$3,'Scenarios MPT'!N$3) | E5: =NORMINV(RAND(),'Scenarios MPT'!H$3,'Scenarios MPT'!O$3) | F5: =NORMINV(RAND(),'Scenarios MPT'!I$3,'Scenarios MPT'!P$3) | G5: =NORMINV(RAND(),'Scenarios MPT'!J$3,'Scenarios MPT'!Q$3) | J5: =J$1*B5 | K5: =K$1*C5 | L5: =L$1*D5 | M5: =M$1*E5 | N5: =N$1*F5 | O5: =O$1*G5 | Q5: =SUM(J5:O5) | S5: Annual Volatility of the Portfolio | T5: =T4*SQRT(12) | W5: -0.11111403 | X5: 0.062354751
A6: 36676 | B6: =NORMINV(RAND(),'Scenarios MPT'!E$3,'Scenarios MPT'!L$3) | C6: =NORMINV(RAND(),'Scenarios MPT'!F$3,'Scenarios MPT'!M$3) | D6: =NORMINV(RAND(),'Scenarios MPT'!G$3,'Scenarios MPT'!N$3) | E6: =NORMINV(RAND(),'Scenarios MPT'!H$3,'Scenarios MPT'!O$3) | F6: =NORMINV(RAND(),'Scenarios MPT'!I$3,'Scenarios MPT'!P$3) | G6: =NORMINV(RAND(),'Scenarios MPT'!J$3,'Scenarios MPT'!Q$3) | J6: =J$1*B6 | K6: =K$1*C6 | L6: =L$1*D6 | M6: =M$1*E6 | N6: =N$1*F6 | O6: =O$1*G6 | Q6: =SUM(J6:O6) | S6: Risk-Free Rate | T6: 0.0165 | W6: -0.1119994 | X6: 0.055878119
A7: 36706 | B7: =NORMINV(RAND(),'Scenarios MPT'!E$3,'Scenarios MPT'!L$3) | C7: =NORMINV(RAND(),'Scenarios MPT'!F$3,'Scenarios MPT'!M$3) | D7: =NORMINV(RAND(),'Scenarios MPT'!G$3,'Scenarios MPT'!N$3) | E7: =NORMINV(RAND(),'Scenarios MPT'!H$3,'Scenarios MPT'!O$3) | F7: =NORMINV(RAND(),'Scenarios MPT'!I$3,'Scenarios MPT'!P$3) | G7: =NORMINV(RAND(),'Scenarios MPT'!J$3,'Scenarios MPT'!Q$3) | J7: =J$1*B7 | K7: =K$1*C7 | L7: =L$1*D7 | M7: =M$1*E7 | N7: =N$1*F7 | O7: =O$1*G7 | Q7: =SUM(J7:O7) | S7: Sharpe Ratio | T7: =(T3-T6)/T5 | W7: -0.12367274 | X7: 0.060193552
A8: 36737 | B8: =NORMINV(RAND(),'Scenarios MPT'!E$3,'Scenarios MPT'!L$3) | C8: =NORMINV(RAND(),'Scenarios MPT'!F$3,'Scenarios MPT'!M$3) | D8: =NORMINV(RAND(),'Scenarios MPT'!G$3,'Scenarios MPT'!N$3) | E8: =NORMINV(RAND(),'Scenarios MPT'!H$3,'Scenarios MPT'!O$3) | F8: =NORMINV(RAND(),'Scenarios MPT'!I$3,'Scenarios MPT'!P$3) | G8: =NORMINV(RAND(),'Scenarios MPT'!J$3,'Scenarios MPT'!Q$3) | J8: =J$1*B8 | K8: =K$1*C8 | L8: =L$1*D8 | M8: =M$1*E8 | N8: =N$1*F8 | O8: =O$1*G8 | Q8: =SUM(J8:O8) | W8: -0.1486993 | X8: 0.055838942
A9: 36768 | B9: =NORMINV(RAND(),'Scenarios MPT'!E$3,'Scenarios MPT'!L$3) | C9: =NORMINV(RAND(),'Scenarios MPT'!F$3,'Scenarios MPT'!M$3) | D9: =NORMINV(RAND(),'Scenarios MPT'!G$3,'Scenarios MPT'!N$3) | E9: =NORMINV(RAND(),'Scenarios MPT'!H$3,'Scenarios MPT'!O$3) | F9: =NORMINV(RAND(),'Scenarios MPT'!I$3,'Scenarios MPT'!P$3) | G9: =NORMINV(RAND(),'Scenarios MPT'!J$3,'Scenarios MPT'!Q$3) | J9: =J$1*B9 | K9: =K$1*C9 | L9: =L$1*D9 | M9: =M$1*E9 | N9: =N$1*F9 | O9: =O$1*G9 | Q9: =SUM(J9:O9) | S9: Simulation Average Annual Return | T9: =AVERAGE(W2:W10001) | W9: -0.066823055 | X9: 0.057745378
A10: 36798 | B10: =NORMINV(RAND(),'Scenarios MPT'!E$3,'Scenarios MPT'!L$3) | C10: =NORMINV(RAND(),'Scenarios MPT'!F$3,'Scenarios MPT'!M$3) | D10: =NORMINV(RAND(),'Scenarios MPT'!G$3,'Scenarios MPT'!N$3) | E10: =NORMINV(RAND(),'Scenarios MPT'!H$3,'Scenarios MPT'!O$3) | F10: =NORMINV(RAND(),'Scenarios MPT'!I$3,'Scenarios MPT'!P$3) | G10: =NORMINV(RAND(),'Scenarios MPT'!J$3,'Scenarios MPT'!Q$3) | J10: =J$1*B10 | K10: =K$1*C10 | L10: =L$1*D10 | M10: =M$1*E10 | N10: =N$1*F10 | O10: =O$1*G10 | Q10: =SUM(J10:O10) | S10: Simulation Average Annual Volatility | T10: =AVERAGE(X2:X10001) | W10: -0.12253714 | X10: 0.058765553
A11: 36829 | B11: =NORMINV(RAND(),'Scenarios MPT'!E$3,'Scenarios MPT'!L$3) | C11: =NORMINV(RAND(),'Scenarios MPT'!F$3,'Scenarios MPT'!M$3) | D11: =NORMINV(RAND(),'Scenarios MPT'!G$3,'Scenarios MPT'!N$3) | E11: =NORMINV(RAND(),'Scenarios MPT'!H$3,'Scenarios MPT'!O$3) | F11: =NORMINV(RAND(),'Scenarios MPT'!I$3,'Scenarios MPT'!P$3) | G11: =NORMINV(RAND(),'Scenarios MPT'!J$3,'Scenarios MPT'!Q$3) | J11: =J$1*B11 | K11: =K$1*C11 | L11: =L$1*D11 | M11: =M$1*E11 | N11: =N$1*F11 | O11: =O$1*G11 | Q11: =SUM(J11:O11) | W11: -0.096802048 | X11: 0.057370698
A12: 36859 | B12: =NORMINV(RAND(),'Scenarios MPT'!E$3,'Scenarios MPT'!L$3) | C12: =NORMINV(RAND(),'Scenarios MPT'!F$3,'Scenarios MPT'!M$3) | D12: =NORMINV(RAND(),'Scenarios MPT'!G$3,'Scenarios MPT'!N$3) | E12: =NORMINV(RAND(),'Scenarios MPT'!H$3,'Scenarios MPT'!O$3) | F12: =NORMINV(RAND(),'Scenarios MPT'!I$3,'Scenarios MPT'!P$3) | G12: =NORMINV(RAND(),'Scenarios MPT'!J$3,'Scenarios MPT'!Q$3) | J12: =J$1*B12 | K12: =K$1*C12 | L12: =L$1*D12 | M12: =M$1*E12 | N12: =N$1*F12 | O12: =O$1*G12 | Q12: =SUM(J12:O12) | S12: Columns B:G draw a new random path on every recalculation (F9). | W12: -0.09422197 | X12: 0.053302177
A13: 36890 | B13: =NORMINV(RAND(),'Scenarios MPT'!E$3,'Scenarios MPT'!L$3) | C13: =NORMINV(RAND(),'Scenarios MPT'!F$3,'Scenarios MPT'!M$3) | D13: =NORMINV(RAND(),'Scenarios MPT'!G$3,'Scenarios MPT'!N$3) | E13: =NORMINV(RAND(),'Scenarios MPT'!H$3,'Scenarios MPT'!O$3) | F13: =NORMINV(RAND(),'Scenarios MPT'!I$3,'Scenarios MPT'!P$3) | G13: =NORMINV(RAND(),'Scenarios MPT'!J$3,'Scenarios MPT'!Q$3) | J13: =J$1*B13 | K13: =K$1*C13 | L13: =L$1*D13 | M13: =M$1*E13 | N13: =N$1*F13 | O13: =O$1*G13 | Q13: =SUM(J13:O13) | S13: W:X hold the stored results of 10,000 simulation runs (T3 and T5 after each recalculation), | W13: -0.14154428 | X13: 0.056152005
A14: 36921 | B14: =NORMINV(RAND(),'Scenarios MPT'!E$3,'Scenarios MPT'!L$3) | C14: =NORMINV(RAND(),'Scenarios MPT'!F$3,'Scenarios MPT'!M$3) | D14: =NORMINV(RAND(),'Scenarios MPT'!G$3,'Scenarios MPT'!N$3) | E14: =NORMINV(RAND(),'Scenarios MPT'!H$3,'Scenarios MPT'!O$3) | F14: =NORMINV(RAND(),'Scenarios MPT'!I$3,'Scenarios MPT'!P$3) | G14: =NORMINV(RAND(),'Scenarios MPT'!J$3,'Scenarios MPT'!Q$3) | J14: =J$1*B14 | K14: =K$1*C14 | L14: =L$1*D14 | M14: =M$1*E14 | N14: =N$1*F14 | O14: =O$1*G14 | Q14: =SUM(J14:O14) | S14: i.e. the output of the RecalculateAndStore macro (see the MC Summary sheet). | W14: -0.094421581 | X14: 0.060759521
A15: 36949 | B15: =NORMINV(RAND(),'Scenarios MPT'!E$3,'Scenarios MPT'!L$3) | C15: =NORMINV(RAND(),'Scenarios MPT'!F$3,'Scenarios MPT'!M$3) | D15: =NORMINV(RAND(),'Scenarios MPT'!G$3,'Scenarios MPT'!N$3) | E15: =NORMINV(RAND(),'Scenarios MPT'!H$3,'Scenarios MPT'!O$3) | F15: =NORMINV(RAND(),'Scenarios MPT'!I$3,'Scenarios MPT'!P$3) | G15: =NORMINV(RAND(),'Scenarios MPT'!J$3,'Scenarios MPT'!Q$3) | J15: =J$1*B15 | K15: =K$1*C15 | L15: =L$1*D15 | M15: =M$1*E15 | N15: =N$1*F15 | O15: =O$1*G15 | Q15: =SUM(J15:O15) | W15: -0.078934119 | X15: 0.065731016
A16: 36980 | B16: =NORMINV(RAND(),'Scenarios MPT'!E$3,'Scenarios MPT'!L$3) | C16: =NORMINV(RAND(),'Scenarios MPT'!F$3,'Scenarios MPT'!M$3) | D16: =NORMINV(RAND(),'Scenarios MPT'!G$3,'Scenarios MPT'!N$3) | E16: =NORMINV(RAND(),'Scenarios MPT'!H$3,'Scenarios MPT'!O$3) | F16: =NORMINV(RAND(),'Scenarios MPT'!I$3,'Scenarios MPT'!P$3) | G16: =NORMINV(RAND(),'Scenarios MPT'!J$3,'Scenarios MPT'!Q$3) | J16: =J$1*B16 | K16: =K$1*C16 | L16: =L$1*D16 | M16: =M$1*E16 | N16: =N$1*F16 | O16: =O$1*G16 | Q16: =SUM(J16:O16) | W16: -0.10264545 | X16: 0.057621199
A17: 37010 | B17: =NORMINV(RAND(),'Scenarios MPT'!E$3,'Scenarios MPT'!L$3) | C17: =NORMINV(RAND(),'Scenarios MPT'!F$3,'Scenarios MPT'!M$3) | D17: =NORMINV(RAND(),'Scenarios MPT'!G$3,'Scenarios MPT'!N$3) | E17: =NORMINV(RAND(),'Scenarios MPT'!H$3,'Scenarios MPT'!O$3) | F17: =NORMINV(RAND(),'Scenarios MPT'!I$3,'Scenarios MPT'!P$3) | G17: =NORMINV(RAND(),'Scenarios MPT'!J$3,'Scenarios MPT'!Q$3) | J17: =J$1*B17 | K17: =K$1*C17 | L17: =L$1*D17 | M17: =M$1*E17 | N17: =N$1*F17 | O17: =O$1*G17 | Q17: =SUM(J17:O17) | W17: -0.061670076 | X17: 0.053236521
A18: 37041 | B18: =NORMINV(RAND(),'Scenarios MPT'!E$3,'Scenarios MPT'!L$3) | C18: =NORMINV(RAND(),'Scenarios MPT'!F$3,'Scenarios MPT'!M$3) | D18: =NORMINV(RAND(),'Scenarios MPT'!G$3,'Scenarios MPT'!N$3) | E18: =NORMINV(RAND(),'Scenarios MPT'!H$3,'Scenarios MPT'!O$3) | F18: =NORMINV(RAND(),'Scenarios MPT'!I$3,'Scenarios MPT'!P$3) | G18: =NORMINV(RAND(),'Scenarios MPT'!J$3,'Scenarios MPT'!Q$3) | J18: =J$1*B18 | K18: =K$1*C18 | L18: =L$1*D18 | M18: =M$1*E18 | N18: =N$1*F18 | O18: =O$1*G18 | Q18: =SUM(J18:O18) | W18: -0.11655647 | X18: 0.059122453
A19: 37071 | B19: =NORMINV(RAND(),'Scenarios MPT'!E$3,'Scenarios MPT'!L$3) | C19: =NORMINV(RAND(),'Scenarios MPT'!F$3,'Scenarios MPT'!M$3) | D19: =NORMINV(RAND(),'Scenarios MPT'!G$3,'Scenarios MPT'!N$3) | E19: =NORMINV(RAND(),'Scenarios MPT'!H$3,'Scenarios MPT'!O$3) | F19: =NORMINV(RAND(),'Scenarios MPT'!I$3,'Scenarios MPT'!P$3) | G19: =NORMINV(RAND(),'Scenarios MPT'!J$3,'Scenarios MPT'!Q$3) | J19: =J$1*B19 | K19: =K$1*C19 | L19: =L$1*D19 | M19: =M$1*E19 | N19: =N$1*F19 | O19: =O$1*G19 | Q19: =SUM(J19:O19) | W19: -0.086123043 | X19: 0.052493453
A20: 37102 | B20: =NORMINV(RAND(),'Scenarios MPT'!E$3,'Scenarios MPT'!L$3) | C20: =NORMINV(RAND(),'Scenarios MPT'!F$3,'Scenarios MPT'!M$3) | D20: =NORMINV(RAND(),'Scenarios MPT'!G$3,'Scenarios MPT'!N$3) | E20: =NORMINV(RAND(),'Scenarios MPT'!H$3,'Scenarios MPT'!O$3) | F20: =NORMINV(RAND(),'Scenarios MPT'!I$3,'Scenarios MPT'!P$3) | G20: =NORMINV(RAND(),'Scenarios MPT'!J$3,'Scenarios MPT'!Q$3) | J20: =J$1*B20 | K20: =K$1*C20 | L20: =L$1*D20 | M20: =M$1*E20 | N20: =N$1*F20 | O20: =O$1*G20 | Q20: =SUM(J20:O20) | W20: -0.095397538 | X20: 0.064931191
A21: 37133 | B21: =NORMINV(RAND(),'Scenarios MPT'!E$3,'Scenarios MPT'!L$3) | C21: =NORMINV(RAND(),'Scenarios MPT'!F$3,'Scenarios MPT'!M$3) | D21: =NORMINV(RAND(),'Scenarios MPT'!G$3,'Scenarios MPT'!N$3) | E21: =NORMINV(RAND(),'Scenarios MPT'!H$3,'Scenarios MPT'!O$3) | F21: =NORMINV(RAND(),'Scenarios MPT'!I$3,'Scenarios MPT'!P$3) | G21: =NORMINV(RAND(),'Scenarios MPT'!J$3,'Scenarios MPT'!Q$3) | J21: =J$1*B21 | K21: =K$1*C21 | L21: =L$1*D21 | M21: =M$1*E21 | N21: =N$1*F21 | O21: =O$1*G21 | Q21: =SUM(J21:O21) | W21: -0.093994873 | X21: 0.064138396
A22: 37163 | B22: =NORMINV(RAND(),'Scenarios MPT'!E$3,'Scenarios MPT'!L$3) | C22: =NORMINV(RAND(),'Scenarios MPT'!F$3,'Scenarios MPT'!M$3) | D22: =NORMINV(RAND(),'Scenarios MPT'!G$3,'Scenarios MPT'!N$3) | E22: =NORMINV(RAND(),'Scenarios MPT'!H$3,'Scenarios MPT'!O$3) | F22: =NORMINV(RAND(),'Scenarios MPT'!I$3,'Scenarios MPT'!P$3) | G22: =NORMINV(RAND(),'Scenarios MPT'!J$3,'Scenarios MPT'!Q$3) | J22: =J$1*B22 | K22: =K$1*C22 | L22: =L$1*D22 | M22: =M$1*E22 | N22: =N$1*F22 | O22: =O$1*G22 | Q22: =SUM(J22:O22) | W22: -0.073548395 | X22: 0.074070646
A23: 37194 | B23: =NORMINV(RAND(),'Scenarios MPT'!E$3,'Scenarios MPT'!L$3) | C23: =NORMINV(RAND(),'Scenarios MPT'!F$3,'Scenarios MPT'!M$3) | D23: =NORMINV(RAND(),'Scenarios MPT'!G$3,'Scenarios MPT'!N$3) | E23: =NORMINV(RAND(),'Scenarios MPT'!H$3,'Scenarios MPT'!O$3) | F23: =NORMINV(RAND(),'Scenarios MPT'!I$3,'Scenarios MPT'!P$3) | G23: =NORMINV(RAND(),'Scenarios MPT'!J$3,'Scenarios MPT'!Q$3) | J23: =J$1*B23 | K23: =K$1*C23 | L23: =L$1*D23 | M23: =M$1*E23 | N23: =N$1*F23 | O23: =O$1*G23 | Q23: =SUM(J23:O23) | W23: -0.062476254 | X23: 0.04524437
A24: 37224 | B24: =NORMINV(RAND(),'Scenarios MPT'!E$3,'Scenarios MPT'!L$3) | C24: =NORMINV(RAND(),'Scenarios MPT'!F$3,'Scenarios MPT'!M$3) | D24: =NORMINV(RAND(),'Scenarios MPT'!G$3,'Scenarios MPT'!N$3) | E24: =NORMINV(RAND(),'Scenarios MPT'!H$3,'Scenarios MPT'!O$3) | F24: =NORMINV(RAND(),'Scenarios MPT'!I$3,'Scenarios MPT'!P$3) | G24: =NORMINV(RAND(),'Scenarios MPT'!J$3,'Scenarios MPT'!Q$3) | J24: =J$1*B24 | K24: =K$1*C24 | L24: =L$1*D24 | M24: =M$1*E24 | N24: =N$1*F24 | O24: =O$1*G24 | Q24: =SUM(J24:O24) | W24: -0.094299333 | X24: 0.05091011
A25: 37255 | B25: =NORMINV(RAND(),'Scenarios MPT'!E$3,'Scenarios MPT'!L$3) | C25: =NORMINV(RAND(),'Scenarios MPT'!F$3,'Scenarios MPT'!M$3) | D25: =NORMINV(RAND(),'Scenarios MPT'!G$3,'Scenarios MPT'!N$3) | E25: =NORMINV(RAND(),'Scenarios MPT'!H$3,'Scenarios MPT'!O$3) | F25: =NORMINV(RAND(),'Scenarios MPT'!I$3,'Scenarios MPT'!P$3) | G25: =NORMINV(RAND(),'Scenarios MPT'!J$3,'Scenarios MPT'!Q$3) | J25: =J$1*B25 | K25: =K$1*C25 | L25: =L$1*D25 | M25: =M$1*E25 | N25: =N$1*F25 | O25: =O$1*G25 | Q25: =SUM(J25:O25) | W25: -0.1089868 | X25: 0.058830863
A26: 37286 | B26: =NORMINV(RAND(),'Scenarios MPT'!E$3,'Scenarios MPT'!L$3) | C26: =NORMINV(RAND(),'Scenarios MPT'!F$3,'Scenarios MPT'!M$3) | D26: =NORMINV(RAND(),'Scenarios MPT'!G$3,'Scenarios MPT'!N$3) | E26: =NORMINV(RAND(),'Scenarios MPT'!H$3,'Scenarios MPT'!O$3) | F26: =NORMINV(RAND(),'Scenarios MPT'!I$3,'Scenarios MPT'!P$3) | G26: =NORMINV(RAND(),'Scenarios MPT'!J$3,'Scenarios MPT'!Q$3) | J26: =J$1*B26 | K26: =K$1*C26 | L26: =L$1*D26 | M26: =M$1*E26 | N26: =N$1*F26 | O26: =O$1*G26 | Q26: =SUM(J26:O26) | W26: -0.052034561 | X26: 0.049582564
... A37: 37620 | B37: =NORMINV(RAND(),'Scenarios MPT'!E$3,'Scenarios MPT'!L$3) | C37: =NORMINV(RAND(),'Scenarios MPT'!F$3,'Scenarios MPT'!M$3) | D37: =NORMINV(RAND(),'Scenarios MPT'!G$3,'Scenarios MPT'!N$3) | E37: =NORMINV(RAND(),'Scenarios MPT'!H$3,'Scenarios MPT'!O$3) | F37: =NORMINV(RAND(),'Scenarios MPT'!I$3,'Scenarios MPT'!P$3) | G37: =NORMINV(RAND(),'Scenarios MPT'!J$3,'Scenarios MPT'!Q$3) | J37: =J$1*B37 | K37: =K$1*C37 | L37: =L$1*D37 | M37: =M$1*E37 | N37: =N$1*F37 | O37: =O$1*G37 | Q37: =SUM(J37:O37) | W37: -0.05544198 | X37: 0.060438898
W38: -0.13977021 | X38: 0.066695566
W39: -0.060820476 | X39: 0.057657043
W40: -0.098785803 | X40: 0.071903043
W41: -0.059843926 | X41: 0.057362782
W42: -0.11557894 | X42: 0.064858331
W43: -0.11230513 | X43: 0.059296816
W44: -0.14015754 | X44: 0.065855842
W45: -0.083695099 | X45: 0.062965737
W46: -0.087642153 | X46: 0.062340127
W47: -0.067865411 | X47: 0.053060251
W48: -0.051547483 | X48: 0.05621906
W49: -0.0962782 | X49: 0.062247107
... W10001: -0.059620155 | X10001: 0.062541595

Sheet MC Sim - Global Financial Crisi
B1: US Large Cap | C1: Dev ex US | D1: EM | E1: UST | F1: US IG Corp Bond | G1: REITs | I1: SAA weights: | J1: ='SAA with CME'!C17 | K1: ='SAA with CME'!D17 | L1: ='SAA with CME'!E17 | M1: ='SAA with CME'!F17 | N1: ='SAA with CME'!G17 | O1: ='SAA with CME'!H17 | Q1: Monthly Portfolio Return | S1: Compounded Annual Portfolio Return | T1: {=GEOMEAN(Q2:Q37+1)^12-1} | W1: Average Annual Return | X1: Annual Volatility of the Portfolio
A2: 39112 | B2: =NORMINV(RAND(),'Scenarios MPT'!E$4,'Scenarios MPT'!L$4) | C2: =NORMINV(RAND(),'Scenarios MPT'!F$4,'Scenarios MPT'!M$4) | D2: =NORMINV(RAND(),'Scenarios MPT'!G$4,'Scenarios MPT'!N$4) | E2: =NORMINV(RAND(),'Scenarios MPT'!H$4,'Scenarios MPT'!O$4) | F2: =NORMINV(RAND(),'Scenarios MPT'!I$4,'Scenarios MPT'!P$4) | G2: =NORMINV(RAND(),'Scenarios MPT'!J$4,'Scenarios MPT'!Q$4) | J2: =J$1*B2 | K2: =K$1*C2 | L2: =L$1*D2 | M2: =M$1*E2 | N2: =N$1*F2 | O2: =O$1*G2 | Q2: =SUM(J2:O2) | S2: Average Monthly Return | T2: =AVERAGE(Q2:Q37) | W2: 0.046504164 | X2: 0.12187615
A3: 39140 | B3: =NORMINV(RAND(),'Scenarios MPT'!E$4,'Scenarios MPT'!L$4) | C3: =NORMINV(RAND(),'Scenarios MPT'!F$4,'Scenarios MPT'!M$4) | D3: =NORMINV(RAND(),'Scenarios MPT'!G$4,'Scenarios MPT'!N$4) | E3: =NORMINV(RAND(),'Scenarios MPT'!H$4,'Scenarios MPT'!O$4) | F3: =NORMINV(RAND(),'Scenarios MPT'!I$4,'Scenarios MPT'!P$4) | G3: =NORMINV(RAND(),'Scenarios MPT'!J$4,'Scenarios MPT'!Q$4) | J3: =J$1*B3 | K3: =K$1*C3 | L3: =L$1*D3 | M3: =M$1*E3 | N3: =N$1*F3 | O3: =O$1*G3 | Q3: =SUM(J3:O3) | S3: Average Annual Return | T3: =(1+T2)^12-1 | W3: -0.091744455 | X3: 0.12242648
A4: 39171 | B4: =NORMINV(RAND(),'Scenarios MPT'!E$4,'Scenarios MPT'!L$4) | C4: =NORMINV(RAND(),'Scenarios MPT'!F$4,'Scenarios MPT'!M$4) | D4: =NORMINV(RAND(),'Scenarios MPT'!G$4,'Scenarios MPT'!N$4) | E4: =NORMINV(RAND(),'Scenarios MPT'!H$4,'Scenarios MPT'!O$4) | F4: =NORMINV(RAND(),'Scenarios MPT'!I$4,'Scenarios MPT'!P$4) | G4: =NORMINV(RAND(),'Scenarios MPT'!J$4,'Scenarios MPT'!Q$4) | J4: =J$1*B4 | K4: =K$1*C4 | L4: =L$1*D4 | M4: =M$1*E4 | N4: =N$1*F4 | O4: =O$1*G4 | Q4: =SUM(J4:O4) | S4: Volatility of Portfolio | T4: =_xlfn.STDEV.S(Q2:Q37) | W4: 0.055209092 | X4: 0.11567287
A5: 39201 | B5: =NORMINV(RAND(),'Scenarios MPT'!E$4,'Scenarios MPT'!L$4) | C5: =NORMINV(RAND(),'Scenarios MPT'!F$4,'Scenarios MPT'!M$4) | D5: =NORMINV(RAND(),'Scenarios MPT'!G$4,'Scenarios MPT'!N$4) | E5: =NORMINV(RAND(),'Scenarios MPT'!H$4,'Scenarios MPT'!O$4) | F5: =NORMINV(RAND(),'Scenarios MPT'!I$4,'Scenarios MPT'!P$4) | G5: =NORMINV(RAND(),'Scenarios MPT'!J$4,'Scenarios MPT'!Q$4) | J5: =J$1*B5 | K5: =K$1*C5 | L5: =L$1*D5 | M5: =M$1*E5 | N5: =N$1*F5 | O5: =O$1*G5 | Q5: =SUM(J5:O5) | S5: Annual Volatility of the Portfolio | T5: =T4*SQRT(12) | W5: -0.088573738 | X5: 0.10108883
A6: 39232 | B6: =NORMINV(RAND(),'Scenarios MPT'!E$4,'Scenarios MPT'!L$4) | C6: =NORMINV(RAND(),'Scenarios MPT'!F$4,'Scenarios MPT'!M$4) | D6: =NORMINV(RAND(),'Scenarios MPT'!G$4,'Scenarios MPT'!N$4) | E6: =NORMINV(RAND(),'Scenarios MPT'!H$4,'Scenarios MPT'!O$4) | F6: =NORMINV(RAND(),'Scenarios MPT'!I$4,'Scenarios MPT'!P$4) | G6: =NORMINV(RAND(),'Scenarios MPT'!J$4,'Scenarios MPT'!Q$4) | J6: =J$1*B6 | K6: =K$1*C6 | L6: =L$1*D6 | M6: =M$1*E6 | N6: =N$1*F6 | O6: =O$1*G6 | Q6: =SUM(J6:O6) | S6: Risk-Free Rate | T6: 0.0165 | W6: 0.025135386 | X6: 0.096398444
A7: 39262 | B7: =NORMINV(RAND(),'Scenarios MPT'!E$4,'Scenarios MPT'!L$4) | C7: =NORMINV(RAND(),'Scenarios MPT'!F$4,'Scenarios MPT'!M$4) | D7: =NORMINV(RAND(),'Scenarios MPT'!G$4,'Scenarios MPT'!N$4) | E7: =NORMINV(RAND(),'Scenarios MPT'!H$4,'Scenarios MPT'!O$4) | F7: =NORMINV(RAND(),'Scenarios MPT'!I$4,'Scenarios MPT'!P$4) | G7: =NORMINV(RAND(),'Scenarios MPT'!J$4,'Scenarios MPT'!Q$4) | J7: =J$1*B7 | K7: =K$1*C7 | L7: =L$1*D7 | M7: =M$1*E7 | N7: =N$1*F7 | O7: =O$1*G7 | Q7: =SUM(J7:O7) | S7: Sharpe Ratio | T7: =(T3-T6)/T5 | W7: 0.10846474 | X7: 0.090396251
A8: 39293 | B8: =NORMINV(RAND(),'Scenarios MPT'!E$4,'Scenarios MPT'!L$4) | C8: =NORMINV(RAND(),'Scenarios MPT'!F$4,'Scenarios MPT'!M$4) | D8: =NORMINV(RAND(),'Scenarios MPT'!G$4,'Scenarios MPT'!N$4) | E8: =NORMINV(RAND(),'Scenarios MPT'!H$4,'Scenarios MPT'!O$4) | F8: =NORMINV(RAND(),'Scenarios MPT'!I$4,'Scenarios MPT'!P$4) | G8: =NORMINV(RAND(),'Scenarios MPT'!J$4,'Scenarios MPT'!Q$4) | J8: =J$1*B8 | K8: =K$1*C8 | L8: =L$1*D8 | M8: =M$1*E8 | N8: =N$1*F8 | O8: =O$1*G8 | Q8: =SUM(J8:O8) | W8: -0.026607595 | X8: 0.10733115
A9: 39324 | B9: =NORMINV(RAND(),'Scenarios MPT'!E$4,'Scenarios MPT'!L$4) | C9: =NORMINV(RAND(),'Scenarios MPT'!F$4,'Scenarios MPT'!M$4) | D9: =NORMINV(RAND(),'Scenarios MPT'!G$4,'Scenarios MPT'!N$4) | E9: =NORMINV(RAND(),'Scenarios MPT'!H$4,'Scenarios MPT'!O$4) | F9: =NORMINV(RAND(),'Scenarios MPT'!I$4,'Scenarios MPT'!P$4) | G9: =NORMINV(RAND(),'Scenarios MPT'!J$4,'Scenarios MPT'!Q$4) | J9: =J$1*B9 | K9: =K$1*C9 | L9: =L$1*D9 | M9: =M$1*E9 | N9: =N$1*F9 | O9: =O$1*G9 | Q9: =SUM(J9:O9) | S9: Simulation Average Annual Return | T9: =AVERAGE(W2:W10001) | W9: -0.12686456 | X9: 0.11211712
A10: 39354 | B10: =NORMINV(RAND(),'Scenarios MPT'!E$4,'Scenarios MPT'!L$4) | C10: =NORMINV(RAND(),'Scenarios MPT'!F$4,'Scenarios MPT'!M$4) | D10: =NORMINV(RAND(),'Scenarios MPT'!G$4,'Scenarios MPT'!N$4) | E10: =NORMINV(RAND(),'Scenarios MPT'!H$4,'Scenarios MPT'!O$4) | F10: =NORMINV(RAND(),'Scenarios MPT'!I$4,'Scenarios MPT'!P$4) | G10: =NORMINV(RAND(),'Scenarios MPT'!J$4,'Scenarios MPT'!Q$4) | J10: =J$1*B10 | K10: =K$1*C10 | L10: =L$1*D10 | M10: =M$1*E10 | N10: =N$1*F10 | O10: =O$1*G10 | Q10: =SUM(J10:O10) | S10: Simulation Average Annual Volatility | T10: =AVERAGE(X2:X10001) | W10: -0.0991907 | X10: 0.10253991
A11: 39385 | B11: =NORMINV(RAND(),'Scenarios MPT'!E$4,'Scenarios MPT'!L$4) | C11: =NORMINV(RAND(),'Scenarios MPT'!F$4,'Scenarios MPT'!M$4) | D11: =NORMINV(RAND(),'Scenarios MPT'!G$4,'Scenarios MPT'!N$4) | E11: =NORMINV(RAND(),'Scenarios MPT'!H$4,'Scenarios MPT'!O$4) | F11: =NORMINV(RAND(),'Scenarios MPT'!I$4,'Scenarios MPT'!P$4) | G11: =NORMINV(RAND(),'Scenarios MPT'!J$4,'Scenarios MPT'!Q$4) | J11: =J$1*B11 | K11: =K$1*C11 | L11: =L$1*D11 | M11: =M$1*E11 | N11: =N$1*F11 | O11: =O$1*G11 | Q11: =SUM(J11:O11) | W11: -0.066079051 | X11: 0.10009094
A12: 39415 | B12: =NORMINV(RAND(),'Scenarios MPT'!E$4,'Scenarios MPT'!L$4) | C12: =NORMINV(RAND(),'Scenarios MPT'!F$4,'Scenarios MPT'!M$4) | D12: =NORMINV(RAND(),'Scenarios MPT'!G$4,'Scenarios MPT'!N$4) | E12: =NORMINV(RAND(),'Scenarios MPT'!H$4,'Scenarios MPT'!O$4) | F12: =NORMINV(RAND(),'Scenarios MPT'!I$4,'Scenarios MPT'!P$4) | G12: =NORMINV(RAND(),'Scenarios MPT'!J$4,'Scenarios MPT'!Q$4) | J12: =J$1*B12 | K12: =K$1*C12 | L12: =L$1*D12 | M12: =M$1*E12 | N12: =N$1*F12 | O12: =O$1*G12 | Q12: =SUM(J12:O12) | S12: Columns B:G draw a new random path on every recalculation (F9). | W12: -0.12833414 | X12: 0.10448746
A13: 39446 | B13: =NORMINV(RAND(),'Scenarios MPT'!E$4,'Scenarios MPT'!L$4) | C13: =NORMINV(RAND(),'Scenarios MPT'!F$4,'Scenarios MPT'!M$4) | D13: =NORMINV(RAND(),'Scenarios MPT'!G$4,'Scenarios MPT'!N$4) | E13: =NORMINV(RAND(),'Scenarios MPT'!H$4,'Scenarios MPT'!O$4) | F13: =NORMINV(RAND(),'Scenarios MPT'!I$4,'Scenarios MPT'!P$4) | G13: =NORMINV(RAND(),'Scenarios MPT'!J$4,'Scenarios MPT'!Q$4) | J13: =J$1*B13 | K13: =K$1*C13 | L13: =L$1*D13 | M13: =M$1*E13 | N13: =N$1*F13 | O13: =O$1*G13 | Q13: =SUM(J13:O13) | S13: W:X hold the stored results of 10,000 simulation runs (T3 and T5 after each recalculation), | W13: 0.014220518 | X13: 0.097829561
A14: 39477 | B14: =NORMINV(RAND(),'Scenarios MPT'!E$4,'Scenarios MPT'!L$4) | C14: =NORMINV(RAND(),'Scenarios MPT'!F$4,'Scenarios MPT'!M$4) | D14: =NORMINV(RAND(),'Scenarios MPT'!G$4,'Scenarios MPT'!N$4) | E14: =NORMINV(RAND(),'Scenarios MPT'!H$4,'Scenarios MPT'!O$4) | F14: =NORMINV(RAND(),'Scenarios MPT'!I$4,'Scenarios MPT'!P$4) | G14: =NORMINV(RAND(),'Scenarios MPT'!J$4,'Scenarios MPT'!Q$4) | J14: =J$1*B14 | K14: =K$1*C14 | L14: =L$1*D14 | M14: =M$1*E14 | N14: =N$1*F14 | O14: =O$1*G14 | Q14: =SUM(J14:O14) | S14: i.e. the output of the RecalculateAndStore macro (see the MC Summary sheet). | W14: 0.022506137 | X14: 0.099949623
A15: 39506 | B15: =NORMINV(RAND(),'Scenarios MPT'!E$4,'Scenarios MPT'!L$4) | C15: =NORMINV(RAND(),'Scenarios MPT'!F$4,'Scenarios MPT'!M$4) | D15: =NORMINV(RAND(),'Scenarios MPT'!G$4,'Scenarios MPT'!N$4) | E15: =NORMINV(RAND(),'Scenarios MPT'!H$4,'Scenarios MPT'!O$4) | F15: =NORMINV(RAND(),'Scenarios MPT'!I$4,'Scenarios MPT'!P$4) | G15: =NORMINV(RAND(),'Scenarios MPT'!J$4,'Scenarios MPT'!Q$4) | J15: =J$1*B15 | K15: =K$1*C15 | L15: =L$1*D15 | M15: =M$1*E15 | N15: =N$1*F15 | O15: =O$1*G15 | Q15: =SUM(J15:O15) | W15: 0.018291025 | X15: 0.08345812
A16: 39537 | B16: =NORMINV(RAND(),'Scenarios MPT'!E$4,'Scenarios MPT'!L$4) | C16: =NORMINV(RAND(),'Scenarios MPT'!F$4,'Scenarios MPT'!M$4) | D16: =NORMINV(RAND(),'Scenarios MPT'!G$4,'Scenarios MPT'!N$4) | E16: =NORMINV(RAND(),'Scenarios MPT'!H$4,'Scenarios MPT'!O$4) | F16: =NORMINV(RAND(),'Scenarios MPT'!I$4,'Scenarios MPT'!P$4) | G16: =NORMINV(RAND(),'Scenarios MPT'!J$4,'Scenarios MPT'!Q$4) | J16: =J$1*B16 | K16: =K$1*C16 | L16: =L$1*D16 | M16: =M$1*E16 | N16: =N$1*F16 | O16: =O$1*G16 | Q16: =SUM(J16:O16) | W16: -0.065107588 | X16: 0.090952928
A17: 39567 | B17: =NORMINV(RAND(),'Scenarios MPT'!E$4,'Scenarios MPT'!L$4) | C17: =NORMINV(RAND(),'Scenarios MPT'!F$4,'Scenarios MPT'!M$4) | D17: =NORMINV(RAND(),'Scenarios MPT'!G$4,'Scenarios MPT'!N$4) | E17: =NORMINV(RAND(),'Scenarios MPT'!H$4,'Scenarios MPT'!O$4) | F17: =NORMINV(RAND(),'Scenarios MPT'!I$4,'Scenarios MPT'!P$4) | G17: =NORMINV(RAND(),'Scenarios MPT'!J$4,'Scenarios MPT'!Q$4) | J17: =J$1*B17 | K17: =K$1*C17 | L17: =L$1*D17 | M17: =M$1*E17 | N17: =N$1*F17 | O17: =O$1*G17 | Q17: =SUM(J17:O17) | W17: -0.085186691 | X17: 0.10883096
A18: 39598 | B18: =NORMINV(RAND(),'Scenarios MPT'!E$4,'Scenarios MPT'!L$4) | C18: =NORMINV(RAND(),'Scenarios MPT'!F$4,'Scenarios MPT'!M$4) | D18: =NORMINV(RAND(),'Scenarios MPT'!G$4,'Scenarios MPT'!N$4) | E18: =NORMINV(RAND(),'Scenarios MPT'!H$4,'Scenarios MPT'!O$4) | F18: =NORMINV(RAND(),'Scenarios MPT'!I$4,'Scenarios MPT'!P$4) | G18: =NORMINV(RAND(),'Scenarios MPT'!J$4,'Scenarios MPT'!Q$4) | J18: =J$1*B18 | K18: =K$1*C18 | L18: =L$1*D18 | M18: =M$1*E18 | N18: =N$1*F18 | O18: =O$1*G18 | Q18: =SUM(J18:O18) | W18: 0.063266854 | X18: 0.094165997
A19: 39628 | B19: =NORMINV(RAND(),'Scenarios MPT'!E$4,'Scenarios MPT'!L$4) | C19: =NORMINV(RAND(),'Scenarios MPT'!F$4,'Scenarios MPT'!M$4) | D19: =NORMINV(RAND(),'Scenarios MPT'!G$4,'Scenarios MPT'!N$4) | E19: =NORMINV(RAND(),'Scenarios MPT'!H$4,'Scenarios MPT'!O$4) | F19: =NORMINV(RAND(),'Scenarios MPT'!I$4,'Scenarios MPT'!P$4) | G19: =NORMINV(RAND(),'Scenarios MPT'!J$4,'Scenarios MPT'!Q$4) | J19: =J$1*B19 | K19: =K$1*C19 | L19: =L$1*D19 | M19: =M$1*E19 | N19: =N$1*F19 | O19: =O$1*G19 | Q19: =SUM(J19:O19) | W19: -0.12728471 | X19: 0.10043718
A20: 39659 | B20: =NORMINV(RAND(),'Scenarios MPT'!E$4,'Scenarios MPT'!L$4) | C20: =NORMINV(RAND(),'Scenarios MPT'!F$4,'Scenarios MPT'!M$4) | D20: =NORMINV(RAND(),'Scenarios MPT'!G$4,'Scenarios MPT'!N$4) | E20: =NORMINV(RAND(),'Scenarios MPT'!H$4,'Scenarios MPT'!O$4) | F20: =NORMINV(RAND(),'Scenarios MPT'!I$4,'Scenarios MPT'!P$4) | G20: =NORMINV(RAND(),'Scenarios MPT'!J$4,'Scenarios MPT'!Q$4) | J20: =J$1*B20 | K20: =K$1*C20 | L20: =L$1*D20 | M20: =M$1*E20 | N20: =N$1*F20 | O20: =O$1*G20 | Q20: =SUM(J20:O20) | W20: -0.048775513 | X20: 0.10740452
A21: 39690 | B21: =NORMINV(RAND(),'Scenarios MPT'!E$4,'Scenarios MPT'!L$4) | C21: =NORMINV(RAND(),'Scenarios MPT'!F$4,'Scenarios MPT'!M$4) | D21: =NORMINV(RAND(),'Scenarios MPT'!G$4,'Scenarios MPT'!N$4) | E21: =NORMINV(RAND(),'Scenarios MPT'!H$4,'Scenarios MPT'!O$4) | F21: =NORMINV(RAND(),'Scenarios MPT'!I$4,'Scenarios MPT'!P$4) | G21: =NORMINV(RAND(),'Scenarios MPT'!J$4,'Scenarios MPT'!Q$4) | J21: =J$1*B21 | K21: =K$1*C21 | L21: =L$1*D21 | M21: =M$1*E21 | N21: =N$1*F21 | O21: =O$1*G21 | Q21: =SUM(J21:O21) | W21: -0.038894539 | X21: 0.11154342
A22: 39720 | B22: =NORMINV(RAND(),'Scenarios MPT'!E$4,'Scenarios MPT'!L$4) | C22: =NORMINV(RAND(),'Scenarios MPT'!F$4,'Scenarios MPT'!M$4) | D22: =NORMINV(RAND(),'Scenarios MPT'!G$4,'Scenarios MPT'!N$4) | E22: =NORMINV(RAND(),'Scenarios MPT'!H$4,'Scenarios MPT'!O$4) | F22: =NORMINV(RAND(),'Scenarios MPT'!I$4,'Scenarios MPT'!P$4) | G22: =NORMINV(RAND(),'Scenarios MPT'!J$4,'Scenarios MPT'!Q$4) | J22: =J$1*B22 | K22: =K$1*C22 | L22: =L$1*D22 | M22: =M$1*E22 | N22: =N$1*F22 | O22: =O$1*G22 | Q22: =SUM(J22:O22) | W22: -0.063037897 | X22: 0.096448871
A23: 39751 | B23: =NORMINV(RAND(),'Scenarios MPT'!E$4,'Scenarios MPT'!L$4) | C23: =NORMINV(RAND(),'Scenarios MPT'!F$4,'Scenarios MPT'!M$4) | D23: =NORMINV(RAND(),'Scenarios MPT'!G$4,'Scenarios MPT'!N$4) | E23: =NORMINV(RAND(),'Scenarios MPT'!H$4,'Scenarios MPT'!O$4) | F23: =NORMINV(RAND(),'Scenarios MPT'!I$4,'Scenarios MPT'!P$4) | G23: =NORMINV(RAND(),'Scenarios MPT'!J$4,'Scenarios MPT'!Q$4) | J23: =J$1*B23 | K23: =K$1*C23 | L23: =L$1*D23 | M23: =M$1*E23 | N23: =N$1*F23 | O23: =O$1*G23 | Q23: =SUM(J23:O23) | W23: -0.039448558 | X23: 0.082031172
