Workbook

Sheet CME - AM1
A1: 10-Year Capital Market Expectations
C3: Expected Return | D3: Expected Vol | E3: Inflation | F3: U.S. Cash | G3: U.S. Intermediate Treasuries | H3: U.S. Long Treasuries | I3: TIPS | J3: U.S. Aggregate Bonds | K3: U.S. Short Duration Government/Credit | L3: U.S. Long Duration Government/Credit | M3: U.S. Inv Grade Corporate Bonds | N3: U.S. Long Corporate Bonds | O3: U.S. High Yield Bonds | P3: U.S. Leveraged Loans | Q3: World Government Bonds hedged | R3: World Government Bonds | S3: World ex-U.S. Government Bonds hedged | T3: World ex-U.S. Government Bonds | U3: Emerging Markets Sovereign Debt | V3: Emerging Markets Local Currency Debt | W3: Emerging Markets Corporate Bonds | X3: U.S. Muni 1-15-Yr Blend | Y3: U.S. Muni High Yield | Z3: U.S. Large Cap | AA3: U.S. Mid Cap | AB3: U.S. Small Cap | AC3: U.S. Large Cap Value | AD3: U.S. Large Cap Growth | AE3: Euro Area Large Cap | AF3: Japanese Equity | AG3: Hong Kong Equity | AH3: UK Large Cap | AI3: EAFE Equity hedged | AJ3: EAFE Equity | AK3: Emerging Markets Equity | AL3: AC Asia ex-Japan Equity | AM3: AC World Equity | AN3: Private Equity | AO3: U.S. Core Direct Real Estate | AP3: U.S. Value-Added Real Estate | AQ3: European ex-UK Prime Direct Real Estate | AR3: Asia Pacific Core Direct Real Estate | AS3: U.S. REITs | AT3: Global Direct Infrastructure Equity | AU3: Global Infrastructure Debt | AV3: Diversified Hedge Funds | AW3: Event Driven Hedge Funds | AX3: Equity Long Bias Hedge Funds | AY3: Relative Value Hedge Funds | AZ3: Macro Hedge Funds | BA3: Direct Lending | BB3: Commodities | BC3: Gold
A4: FIXED INCOME | B4: Inflation | C4: 0.02439 | D4: 0.01362 | E4: 1
A5: FIXED INCOME | B5: U.S. Cash | C5: 0.01846 | D5: 0.00459 | E5: 0.084 | F5: 1
A6: FIXED INCOME | B6: U.S. Intermediate Treasuries | C6: 0.02253 | D6: 0.06043 | E6: -0.183 | F6: 0.092 | G6: 1
A7: FIXED INCOME | B7: U.S. Long Treasuries | C7: 0.01808 | D7: 0.13723 | E7: -0.2589 | F7: 0.028 | G7: 0.97 | H7: 1
A8: FIXED INCOME | B8: TIPS | C8: 0.03773 | D8: 0.05684 | E8: 0.05 | F8: 0.066 | G8: 0.68 | H8: 0.5 | I8: 1
A9: FIXED INCOME | B9: U.S. Aggregate Bonds | C9: 0.0296 | D9: 0.03332 | E9: -0.1439 | F9: 0.091 | G9: 0.92 | H9: 0.75 | I9: 0.79 | J9: 1
A10: FIXED INCOME | B10: U.S. Short Duration Government/Credit | C10: 0.03315 | D10: 0.01602 | E10: -0.1075 | F10: 0.38 | G10: 0.67 | H10: 0.42 | I10: 0.72 | J10: 0.77 | K10: 1
A11: FIXED INCOME | B11: U.S. Long Duration Government/Credit | C11: 0.03336 | D11: 0.08963 | E11: -0.217 | F11: -0.01884 | G11: 0.85 | H11: 0.94 | I11: 0.63 | J11: 0.84 | K11: 0.51 | L11: 1
A12: FIXED INCOME | B12: U.S. Inv Grade Corporate Bonds | C12: 0.03277 | D12: 0.05834 | E12: -0.1416 | F12: -0.0483 | G12: 0.52 | H12: 0.47 | I12: 0.69 | J12: 0.75 | K12: 0.56 | L12: 0.78 | M12: 1
A13: FIXED INCOME | B13: U.S. Long Corporate Bonds | C13: 0.03945 | D13: 0.1056 | E13: -0.166 | F13: -0.06878 | G13: 0.5 | H13: 0.55 | I13: 0.59 | J13: 0.9 | K13: 0.46 | L13: 0.8 | M13: 0.91 | N13: 1
A14: FIXED INCOME | B14: U.S. High Yield Bonds | C14: 0.05623 | D14: 0.09885 | E14: 0.13 | F14: -0.107 | G14: -0.2141 | H14: -0.299 | I14: 0.33 | J14: 0.18 | K14: 0.13 | L14: 0.12 | M14: 0.56 | N14: 0.51 | O14: 1
A15: FIXED INCOME | B15: U.S. Leveraged Loans | C15: 0.05247 | D15: 0.05672 | E15: 0.22 | F15: -0.1167 | G15: -0.3685 | H15: -0.2901 | I15: 0.066 | J15: 0 | K15: -0.1263 | L15: 0.022 | M15: 0.38 | N15: 0.37 | O15: 0.74 | P15: 1
A16: FIXED INCOME | B16: World Government Bonds hedged | C16: 0.01826 | D16: 0.0298 | E16: -0.2726 | F16: 0.085 | G16: 0.95 | H16: 0.83 | I16: 0.52 | J16: 0.8 | K16: 0.56 | L16: 0.77 | M16: 0.5 | N16: 0.57 | O16: -0.2255 | P16: -0.3225 | Q16: 1
A17: FIXED INCOME | B17: World Government Bonds | C17: 0.02107 | D17: 0.05941 | E17: -0.03744 | F17: 0.13 | G17: 0.6 | H17: 0.48 | I17: 0.6 | J17: 0.66 | K17: 0.68 | L17: 0.58 | M17: 0.54 | N17: 0.5 | O17: 0.19 | P17: -0.1266 | Q17: 0.59 | R17: 1
A18: FIXED INCOME | B18: World ex-U.S. Government Bonds hedged | C18: 0.01805 | D18: 0.02725 | E18: -0.2814 | F18: 0.055 | G18: 0.78 | H18: 0.7 | I18: 0.39 | J18: 0.75 | K18: 0.51 | L18: 0.79 | M18: 0.43 | N18: 0.54 | O18: -0.152 | P18: -0.2818 | Q18: 1 | R18: 0.52 | S18: 1
A19: FIXED INCOME | B19: World ex-U.S. Government Bonds | C19: 0.02179 | D19: 0.07258 | E19: 0 | F19: 0.09 | G19: 0.47 | H19: 0.35 | I19: 0.6 | J19: 0.57 | K19: 0.66 | L19: 0.47 | M19: 0.52 | N19: 0.44 | O19: 0.27 | P19: -0.04836 | Q19: 0.43 | R19: 0.93 | S19: 0.38 | T19: 1
A20: FIXED INCOME | B20: Emerging Markets Sovereign Debt | C20: 0.05046 | D20: 0.09404 | E20: -0.01939 | F20: -0.0211 | G20: 0.26 | H20: 0.11 | I20: 0.62 | J20: 0.56 | K20: 0.43 | L20: 0.45 | M20: 0.8 | N20: 0.7 | O20: 0.78 | P20: 0.45 | Q20: 0.23 | R20: 0.52 | S20: 0.26 | T20: 0.55 | U20: 1
A21: FIXED INCOME | B21: Emerging Markets Local Currency Debt | C21: 0.06055 | D21: 0.13631 | E21: 0.11 | F21: 0.13 | G21: 0.1 | H21: -0.02829 | I21: 0.49 | J21: 0.41 | K21: 0.4 | L21: 0.27 | M21: 0.5 | N21: 0.44 | O21: 0.61 | P21: 0.36 | Q21: 0.12 | R21: 0.56 | S21: 0.099 | T21: 0.62 | U21: 0.77 | V21: 1
A22: FIXED INCOME | B22: Emerging Markets Corporate Bonds | C22: 0.05985 | D22: 0.08574 | E22: 0.039 | F22: -0.05716 | G22: 0.1 | H22: -0.02001 | I22: 0.53 | J22: 0.5 | K22: 0.45 | L22: 0.4 | M22: 0.79 | N22: 0.65 | O22: 0.74 | P22: 0.5 | Q22: 0.1 | R22: 0.43 | S22: 0.13 | T22: 0.47 | U22: 0.84 | V22: 0.66 | W22: 1
A23: FIXED INCOME | B23: U.S. Muni 1-15-Yr Blend | C23: 0.02671 | D23: 0.02819 | E23: -0.08199 | F23: 0.02 | G23: 0.5 | H23: 0.46 | I23: 0.5 | J23: 0.68 | K23: 0.43 | L23: 0.57 | M23: 0.57 | N23: 0.47 | O23: 0.24 | P23: 0.067 | Q23: 0.5 | R23: 0.39 | S23: 0.51 | T23: 0.33 | U23: 0.45 | V23: 0.22 | W23: 0.36 | X23: 1
A24: FIXED INCOME | B24: U.S. Muni High Yield | C24: 0.03854 | D24: 0.07316 | E24: 0.17 | F24: -0.1204 | G24: 0.019 | H24: 0.01 | I24: 0.29 | J24: 0.25 | K24: 0.028 | L24: 0.2 | M24: 0.35 | N24: 0.34 | O24: 0.44 | P24: 0.38 | Q24: 0.06 | R24: 0.03 | S24: 0.083 | T24: 0.037 | U24: 0.4 | V24: 0.21 | W24: 0.36 | X24: 0.53 | Y24: 1
A25: EQUITIES | B25: U.S. Large Cap | C25: 0.06271 | D25: 0.1411 | E25: 0.065 | F25: -0.05663 | G25: -0.326 | H25: -0.344 | I25: 0.06 | J25: 0 | K25: -0.03712 | L25: -0.03675 | M25: 0.3 | N25: 0.22 | O25: 0.6 | P25: 0.63 | Q25: -0.2303 | R25: 0.15 | S25: -0.1959 | T25: 0.22 | U25: 0.5 | V25: 0.67 | W25: 0.56 | X25: -0.009152 | Y25: 0.2 | Z25: 1
A26: EQUITIES | B26: U.S. Mid Cap | C26: 0.06479 | D26: 0.18065 | E26: 0.083 | F26: -0.07873 | G26: -0.3408 | H26: -0.3739 | I26: 0.084 | J26: 0 | K26: -0.0426 | L26: -0.04331 | M26: 0.3 | N26: 0.27 | O26: 0.8 | P26: 0.68 | Q26: -0.3018 | R26: 0.11 | S26: -0.1891 | T26: 0.19 | U26: 0.6 | V26: 0.57 | W26: 0.53 | X26: 0.02 | Y26: 0.24 | Z26: 0.98 | AA26: 1
A27: EQUITIES | B27: U.S. Small Cap | C27: 0.07251 | D27: 0.18014 | E27: 0.063 | F27: -0.07352 | G27: -0.3157 | H27: -0.3544 | I27: 0 | J27: -0.07925 | K27: -0.103 | L27: -0.103 | M27: 0.24 | N27: 0.16 | O27: 0.61 | P27: 0.5 | Q27: -0.309 | R27: 0.064 | S27: -0.248 | T27: 0.14 | U27: 0.43 | V27: 0.53 | W27: 0.45 | X27: -0.05318 | Y27: 0.14 | Z27: 0.84 | AA27: 0.98 | AB27: 1
A28: EQUITIES | B28: U.S. Large Cap Value | C28: 0.05818 | D28: 0.1411 | E28: 0.056 | F28: -0.0642 | G28: -0.289 | H28: -0.3573 | I28: 0.037 | J28: 0 | K28: -0.03199 | L28: -0.02767 | M28: 0.29 | N28: 0.24 | O28: 0.67 | P28: 0.61 | Q28: -0.2389 | R28: 0.17 | S28: -0.1861 | T28: 0.24 | U28: 0.49 | V28: 0.63 | W28: 0.54 | X28: -0.01891 | Y28: 0.19 | Z28: 1 | AA28: 0.93 | AB28: 0.84 | AC28: 1
A29: EQUITIES | B29: U.S. Large Cap Growth | C29: 0.06476 | D29: 0.14936 | E29: 0.074 | F29: -0.05688 | G29: -0.2899 | H29: -0.378 | I29: 0.089 | J29: -0.009683 | K29: -0.04308 | L29: -0.06076 | M29: 0.3 | N29: 0.23 | O29: 0.74 | P29: 0.65 | Q29: -0.2887 | R29: 0.13 | S29: -0.2033 | T29: 0.2 | U29: 0.56 | V29: 0.57 | W29: 0.61 | X29: 0 | Y29: 0.21 | Z29: 0.98 | AA29: 1 | AB29: 0.9 | AC29: 0.95 | AD29: 1
A30: EQUITIES | B30: Euro Area Large Cap | C30: 0.07364 | D30: 0.2068 | E30: 0.053 | F30: 0.041 | G30: -0.2584 | H30: -0.3298 | I30: 0.15 | J30: 0.068 | K30: 0.11 | L30: 0 | M30: 0.34 | N30: 0.28 | O30: 0.7 | P30: 0.54 | Q30: -0.2125 | R30: 0.32 | S30: -0.1825 | T30: 0.42 | U30: 0.62 | V30: 0.6 | W30: 0.59 | X30: 0.019 | Y30: 0.18 | Z30: 0.82 | AA30: 0.78 | AB30: 0.75 | AC30: 0.8 | AD30: 0.86 | AE30: 1
A31: EQUITIES | B31: Japanese Equity | C31: 0.05853 | D31: 0.15905 | E31: 0.022 | F31: -0.08777 | G31: -0.221 | H31: -0.224 | I31: 0.12 | J31: 0.075 | K31: 0.049 | L31: 0.07 | M31: 0.35 | N31: 0.33 | O31: 0.6 | P31: 0.53 | Q31: -0.1767 | R31: 0.15 | S31: -0.1469 | T31: 0.24 | U31: 0.5 | V31: 0.59 | W31: 0.56 | X31: -0.01082 | Y31: 0.12 | Z31: 0.67 | AA31: 0.72 | AB31: 0.62 | AC31: 0.66 | AD31: 0.65 | AE31: 0.7 | AF31: 1
A32: EQUITIES | B32: Hong Kong Equity | C32: 0.08143 | D32: 0.22085 | E32: -0.01061 | F32: 0.083 | G32: -0.1709 | H32: -0.2809 | I32: 0.15 | J32: 0.13 | K32: 0.15 | L32: 0.098 | M32: 0.42 | N32: 0.36 | O32: 0.64 | P32: 0.5 | Q32: -0.1506 | R32: 0.23 | S32: -0.1283 | T32: 0.29 | U32: 0.59 | V32: 0.6 | W32: 0.71 | X32: 0.043 | Y32: 0.21 | Z32: 0.74 | AA32: 0.67 | AB32: 0.6 | AC32: 0.68 | AD32: 0.7 | AE32: 0.73 | AF32: 0.58 | AG32: 1
A33: EQUITIES | B33: UK Large Cap | C33: 0.07674 | D33: 0.15629 | E33: 0.1 | F33: 0 | G33: -0.3225 | H33: -0.3792 | I33: 0.11 | J33: 0.04 | K33: 0.055 | L33: -0.01818 | M33: 0.39 | N33: 0.3 | O33: 0.72 | P33: 0.63 | Q33: -0.2831 | R33: 0.26 | S33: -0.2429 | T33: 0.3 | U33: 0.58 | V33: 0.66 | W33: 0.66 | X33: 0.02 | Y33: 0.29 | Z33: 0.94 | AA33: 0.87 | AB33: 0.78 | AC33: 0.76 | AD33: 0.84 | AE33: 0.99 | AF33: 0.77 | AG33: 0.84 | AH33: 1
A34: EQUITIES | B34: EAFE Equity hedged | C34: 0.06117 | D34: 0.14796 | E34: 0.01 | F34: -0.02867 | G34: -0.3668 | H34: -0.3703 | I34: -0.02153 | J34: -0.02919 | K34: -0.06658 | L34: -0.03299 | M34: 0.3 | N34: 0.26 | O34: 0.7 | P34: 0.65 | Q34: -0.2752 | R34: -0.02129 | S34: -0.1927 | T34: 0.04 | U34: 0.59 | V34: 0.61 | W34: 0.54 | X34: -0.01993 | Y34: 0.25 | Z34: 0.82 | AA34: 0.88 | AB34: 0.8 | AC34: 0.86 | AD34: 0.95 | AE34: 0.87 | AF34: 0.79 | AG34: 0.68 | AH34: 0.94 | AI34: 1
A35: EQUITIES | B35: EAFE Equity | C35: 0.07392 | D35: 0.17369 | E35: 0.055 | F35: 0.011 | G35: -0.2744 | H35: -0.3471 | I35: 0.17 | J35: 0.083 | K35: 0.11 | L35: 0.038 | M35: 0.46 | N35: 0.38 | O35: 0.78 | P35: 0.67 | Q35: -0.1986 | R35: 0.33 | S35: -0.1699 | T35: 0.43 | U35: 0.69 | V35: 0.7 | W35: 0.72 | X35: 0.03 | Y35: 0.19 | Z35: 0.89 | AA35: 0.92 | AB35: 0.77 | AC35: 0.95 | AD35: 0.89 | AE35: 0.93 | AF35: 0.87 | AG35: 0.8 | AH35: 1 | AI35: 0.97 | AJ35: 1
A36: EQUITIES | B36: Emerging Markets Equity | C36: 0.08348 | D36: 0.21458 | E36: 0.086 | F36: 0.084 | G36: -0.219 | H36: -0.2973 | I36: 0.24 | J36: 0.14 | K36: 0.19 | L36: 0.062 | M36: 0.48 | N36: 0.33 | O36: 0.73 | P36: 0.53 | Q36: -0.1965 | R36: 0.34 | S36: -0.1491 | T36: 0.4 | U36: 0.68 | V36: 0.84 | W36: 0.8 | X36: 0.052 | Y36: 0.27 | Z36: 0.74 | AA36: 0.75 | AB36: 0.64 | AC36: 0.73 | AD36: 0.73 | AE36: 0.81 | AF36: 0.63 | AG36: 0.88 | AH36: 0.75 | AI36: 0.81 | AJ36: 0.82 | AK36: 1
A37: EQUITIES | B37: AC Asia ex-Japan Equity | C37: 0.09839 | D37: 0.21267 | E37: 0.009 | F37: 0.073 | G37: -0.1852 | H37: -0.2296 | I37: 0.24 | J37: 0.16 | K37: 0.17 | L37: 0.1 | M37: 0.47 | N37: 0.39 | O37: 0.75 | P37: 0.6 | Q37: -0.1353 | R37: 0.29 | S37: -0.107 | T37: 0.32 | U37: 0.64 | V37: 0.78 | W37: 0.71 | X37: 0.063 | Y37: 0.25 | Z37: 0.79 | AA37: 0.79 | AB37: 0.67 | AC37: 0.72 | AD37: 0.79 | AE37: 0.8 | AF37: 0.62 | AG37: 0.9 | AH37: 0.8 | AI37: 0.82 | AJ37: 0.78 | AK37: 0.96 | AL37: 1
A38: EQUITIES | B38: AC World Equity | C38: 0.06744 | D38: 0.17287 | E38: 0.066 | F38: -0.01042 | G38: -0.2692 | H38: -0.3588 | I38: 0.13 | J38: 0.051 | K38: 0.056 | L38: 0 | M38: 0.42 | N38: 0.29 | O38: 0.82 | P38: 0.66 | Q38: -0.2502 | R38: 0.28 | S38: -0.2004 | T38: 0.31 | U38: 0.65 | V38: 0.73 | W38: 0.67 | X38: 0.021 | Y38: 0.22 | Z38: 1 | AA38: 0.96 | AB38: 0.81 | AC38: 0.95 | AD38: 1 | AE38: 0.97 | AF38: 0.78 | AG38: 0.89 | AH38: 0.99 | AI38: 0.84 | AJ38: 0.91 | AK38: 0.9 | AL38: 0.85 | AM38: 1
A39: ALTERNATIVES | B39: Private Equity | C39: 0.08072 | D39: 0.21814 | E39: 0.07 | F39: -0.0207 | G39: -0.249 | H39: -0.2999 | I39: 0.09 | J39: 0.032 | K39: 0.029 | L39: -0.00992 | M39: 0.29 | N39: 0.23 | O39: 0.71 | P39: 0.61 | Q39: -0.2251 | R39: 0.19 | S39: -0.1641 | T39: 0.27 | U39: 0.52 | V39: 0.55 | W39: 0.52 | X39: 0.019 | Y39: 0.2 | Z39: 0.77 | AA39: 0.74 | AB39: 0.81 | AC39: 0.8 | AD39: 0.89 | AE39: 0.8 | AF39: 0.64 | AG39: 0.68 | AH39: 0.75 | AI39: 0.71 | AJ39: 0.8 | AK39: 0.74 | AL39: 0.7 | AM39: 0.92 | AN39: 1
A40: ALTERNATIVES | B40: U.S. Core Direct Real Estate | C40: 0.05694 | D40: 0.10436 | E40: -0.01096 | F40: -0.0289 | G40: -0.03686 | H40: -0.05423 | I40: 0.049 | J40: 0.048 | K40: 0 | L40: 0.03 | M40: 0.11 | N40: 0.1 | O40: 0.23 | P40: 0.2 | Q40: -0.01956 | R40: 0.075 | S40: 0 | T40: 0.1 | U40: 0.2 | V40: 0.21 | W40: 0.17 | X40: 0.052 | Y40: 0.078 | Z40: 0.3 | AA40: 0.3 | AB40: 0.28 | AC40: 0.29 | AD40: 0.27 | AE40: 0.27 | AF40: 0.2 | AG40: 0.18 | AH40: 0.21 | AI40: 0.27 | AJ40: 0.26 | AK40: 0.2 | AL40: 0.2 | AM40: 0.26 | AN40: 0.27 | AO40: 1
A41: ALTERNATIVES | B41: U.S. Value-Added Real Estate | C41: 0.06618 | D41: 0.12434 | E41: -0.01017 | F41: -0.027 | G41: -0.04104 | H41: -0.07043 | I41: 0.037 | J41: 0.038 | K41: -0.009124 | L41: 0.03 | M41: 0.12 | N41: 0.1 | O41: 0.24 | P41: 0.2 | Q41: -0.02085 | R41: 0.088 | S41: 0 | T41: 0.1 | U41: 0.2 | V41: 0.23 | W41: 0.15 | X41: 0.054 | Y41: 0.072 | Z41: 0.33 | AA41: 0.37 | AB41: 0.34 | AC41: 0.32 | AD41: 0.33 | AE41: 0.27 | AF41: 0.23 | AG41: 0.18 | AH41: 0.25 | AI41: 0.28 | AJ41: 0.27 | AK41: 0.23 | AL41: 0.22 | AM41: 0.3 | AN41: 0.3 | AO41: 0.9 | AP41: 1
...

Sheet CME - AM2
A1: 10-Year Capital Market Expectations
B3: Asset Class | C3: Representative Index | D3: Expected Return | E3: Expected Vol | F3: U.S. Equity | G3: U.S. Large Cap Equity | H3: U.S. Mid Cap Equity | I3: U.S. Small Cap Equity | J3: U.S. Micro Cap Equity | K3: Global Equity | L3: International Developed Equity | M3: International Small Cap Equity | N3: Emerging Equity | O3: U.S. Aggregate | P3: U.S. Treasury | Q3: U.S. Treasury Bills | R3: U.S. Intermediate Treasury | S3: U.S. Long Treasury | T3: U.S. Investment Grade Credit | U3: U.S. Intermediate Investment Grade Credit | V3: U.S. Long Investment Grade Credit | W3: U.S. TIPS | X3: U.S. Agencies | Y3: U.S. MBS | Z3: U.S. Investment Grade CMBS | AA3: U.S. Intermediate Municipal | AB3: U.S. Short Municipal | AC3: U.S. High Yield | AD3: U.S. Bank Loans | AE3: Global Aggregate Ex-US | AF3: Global Treasury Ex-US | AG3: Global Corporate Ex-US | AH3: Emerging Markets Sovereign USD | AI3: Emerging Markets Corporate USD | AJ3: Emerging Markets Sovereign Local Currency | AK3: Absolute Return | AL3: Hedge Funds | AM3: Hedge Funds – Equity Hedge | AN3: Hedge Funds – Event Driven | AO3: Hedge Funds – Macro | AP3: Hedge Funds – Relative Value | AQ3: Hedge Funds – Managed Futures | AR3: Commodities | AS3: Global Natural Resources Equity | AT3: U.S. Core Real Estate | AU3: U.S. Residential Real Estate | AV3: Timberland | AW3: Farmland | AX3: U.S. REIT | AY3: Global REIT | AZ3: U.S. Private Equity | BA3: U.S. Venture Capital | BB3: Energy Infrastructure
A4: Equity | B4: U.S. Equity | C4: Russell 3000 | D4: 0.0656 | E4: 0.1601 | F4: 1 | G4: 1 | H4: 0.92 | I4: 0.9 | J4: 0.88 | K4: 0.95 | L4: 0.9 | M4: 0.81 | N4: 0.85 | O4: -0.04839 | P4: -0.3259 | Q4: -0.1002 | R4: -0.329 | S4: -0.2988 | T4: 0.24 | U4: 0.24 | V4: 0.21 | W4: 0.064 | X4: -0.1369 | Y4: -0.1273 | Z4: 0.39 | AA4: -0.04354 | AB4: -0.1091 | AC4: 0.67 | AD4: 0.49 | AE4: 0.27 | AF4: 0.16 | AG4: 0.47 | AH4: 0.53 | AI4: 0.57 | AJ4: 0.63 | AK4: 0.63 | AL4: 0.81 | AM4: 0.85 | AN4: 0.72 | AO4: 0.22 | AP4: 0.64 | AQ4: -0.09348 | AR4: 0.39 | AS4: 0.66 | AT4: 0.46 | AU4: 0.1 | AV4: 0.42 | AW4: 0.35 | AX4: 0.69 | AY4: 0.73 | AZ4: 0.94 | BA4: 0.65 | BB4: 0.51
A5: Equity | B5: U.S. Large Cap Equity | C5: Russell 1000 | D5: 0.0605 | E5: 0.1508 | F5: 1 | G5: 1 | H5: 0.98 | I5: 0.84 | J5: 0.82 | K5: 0.94 | L5: 0.94 | M5: 0.78 | N5: 0.77 | O5: -0.04154 | P5: -0.312 | Q5: -0.1114 | R5: -0.3053 | S5: -0.3162 | T5: 0.25 | U5: 0.27 | V5: 0.21 | W5: 0.083 | X5: -0.1096 | Y5: -0.125 | Z5: 0.4 | AA5: -0.0293 | AB5: -0.1312 | AC5: 0.68 | AD5: 0.58 | AE5: 0.23 | AF5: 0.16 | AG5: 0.49 | AH5: 0.54 | AI5: 0.59 | AJ5: 0.58 | AK5: 0.7 | AL5: 0.79 | AM5: 0.89 | AN5: 0.75 | AO5: 0.21 | AP5: 0.7 | AQ5: -0.08217 | AR5: 0.39 | AS5: 0.7 | AT5: 0.48 | AU5: 0.1 | AV5: 0.38 | AW5: 0.31 | AX5: 0.64 | AY5: 0.78 | AZ5: 0.93 | BA5: 0.7 | BB5: 0.49
A6: Equity | B6: U.S. Mid Cap Equity | C6: Russell Mid Cap | D6: 0.0624 | E6: 0.1781 | F6: 0.92 | G6: 0.98 | H6: 1 | I6: 0.86 | J6: 0.86 | K6: 0.89 | L6: 0.92 | M6: 0.86 | N6: 0.71 | O6: -0.01844 | P6: -0.3171 | Q6: -0.1059 | R6: -0.3 | S6: -0.306 | T6: 0.26 | U6: 0.29 | V6: 0.23 | W6: 0.12 | X6: -0.1025 | Y6: -0.114 | Z6: 0.39 | AA6: 0 | AB6: -0.11 | AC6: 0.81 | AD6: 0.6 | AE6: 0.27 | AF6: 0.16 | AG6: 0.5 | AH6: 0.57 | AI6: 0.63 | AJ6: 0.65 | AK6: 0.68 | AL6: 0.93 | AM6: 0.95 | AN6: 0.9 | AO6: 0.27 | AP6: 0.8 | AQ6: -0.07699 | AR6: 0.44 | AS6: 0.68 | AT6: 0.5 | AU6: 0.1 | AV6: 0.4 | AW6: 0.25 | AX6: 0.67 | AY6: 0.7 | AZ6: 0.8 | BA6: 0.77 | BB6: 0.47
A7: Equity | B7: U.S. Small Cap Equity | C7: Russell 2000 | D7: 0.0746 | E7: 0.1976 | F7: 0.9 | G7: 0.84 | H7: 0.86 | I7: 1 | J7: 0.94 | K7: 0.93 | L7: 0.76 | M7: 0.73 | N7: 0.71 | O7: -0.08298 | P7: -0.3121 | Q7: -0.0982 | R7: -0.3397 | S7: -0.3582 | T7: 0.19 | U7: 0.19 | V7: 0.18 | W7: 0.02 | X7: -0.138 | Y7: -0.1799 | Z7: 0.35 | AA7: -0.06356 | AB7: -0.1349 | AC7: 0.7 | AD7: 0.56 | AE7: 0.18 | AF7: 0.11 | AG7: 0.38 | AH7: 0.45 | AI7: 0.57 | AJ7: 0.54 | AK7: 0.63 | AL7: 0.8 | AM7: 0.86 | AN7: 0.71 | AO7: 0.22 | AP7: 0.63 | AQ7: -0.103 | AR7: 0.37 | AS7: 0.59 | AT7: 0.44 | AU7: 0.087 | AV7: 0.35 | AW7: 0.31 | AX7: 0.64 | AY7: 0.77 | AZ7: 0.9 | BA7: 0.69 | BB7: 0.47
A8: Equity | B8: U.S. Micro Cap Equity | C8: Dow Jones Wilshire U.S. Micro-Cap | D8: 0.0689 | E8: 0.2229 | F8: 0.88 | G8: 0.82 | H8: 0.86 | I8: 0.94 | J8: 1 | K8: 0.84 | L8: 0.67 | M8: 0.81 | N8: 0.65 | O8: -0.115 | P8: -0.3466 | Q8: -0.09018 | R8: -0.405 | S8: -0.3859 | T8: 0.16 | U8: 0.18 | V8: 0.13 | W8: 0.021 | X8: -0.1729 | Y8: -0.215 | Z8: 0.32 | AA8: -0.06468 | AB8: -0.1141 | AC8: 0.67 | AD8: 0.55 | AE8: 0.19 | AF8: 0.092 | AG8: 0.39 | AH8: 0.45 | AI8: 0.5 | AJ8: 0.53 | AK8: 0.72 | AL8: 0.81 | AM8: 0.93 | AN8: 0.89 | AO8: 0.25 | AP8: 0.66 | AQ8: -0.105 | AR8: 0.34 | AS8: 0.57 | AT8: 0.44 | AU8: 0.13 | AV8: 0.3 | AW8: 0.2 | AX8: 0.62 | AY8: 0.65 | AZ8: 0.84 | BA8: 0.76 | BB8: 0.47
A9: Equity | B9: Global Equity | C9: MSCI ACWI | D9: 0.0667 | E9: 0.149 | F9: 0.95 | G9: 0.94 | H9: 0.89 | I9: 0.93 | J9: 0.84 | K9: 1 | L9: 0.99 | M9: 0.86 | N9: 0.92 | O9: 0.0098 | P9: -0.287 | Q9: -0.0942 | R9: -0.3056 | S9: -0.3216 | T9: 0.28 | U9: 0.35 | V9: 0.27 | W9: 0.16 | X9: -0.08073 | Y9: -0.09871 | Z9: 0.37 | AA9: -0.009987 | AB9: -0.0936 | AC9: 0.79 | AD9: 0.53 | AE9: 0.35 | AF9: 0.3 | AG9: 0.6 | AH9: 0.7 | AI9: 0.65 | AJ9: 0.7 | AK9: 0.69 | AL9: 0.95 | AM9: 0.83 | AN9: 0.78 | AO9: 0.3 | AP9: 0.7 | AQ9: -0.07463 | AR9: 0.5 | AS9: 0.86 | AT9: 0.43 | AU9: 0.12 | AV9: 0.47 | AW9: 0.32 | AX9: 0.7 | AY9: 0.77 | AZ9: 0.83 | BA9: 0.62 | BB9: 0.51
A10: Equity | B10: International Developed Equity | C10: MSCI EAFE | D10: 0.0657 | E10: 0.1878 | F10: 0.9 | G10: 0.94 | H10: 0.92 | I10: 0.76 | J10: 0.67 | K10: 0.99 | L10: 1 | M10: 0.97 | N10: 0.91 | O10: 0.03 | P10: -0.244 | Q10: -0.06931 | R10: -0.2538 | S10: -0.3051 | T10: 0.32 | U10: 0.38 | V10: 0.3 | W10: 0.17 | X10: -0.04366 | Y10: -0.05725 | Z10: 0.37 | AA10: 0 | AB10: -0.0748 | AC10: 0.7 | AD10: 0.54 | AE10: 0.45 | AF10: 0.32 | AG10: 0.73 | AH10: 0.61 | AI10: 0.56 | AJ10: 0.7 | AK10: 0.7 | AL10: 0.81 | AM10: 0.93 | AN10: 0.76 | AO10: 0.3 | AP10: 0.68 | AQ10: -0.06168 | AR10: 0.5 | AS10: 0.84 | AT10: 0.45 | AU10: 0.12 | AV10: 0.5 | AW10: 0.36 | AX10: 0.61 | AY10: 0.8 | AZ10: 0.81 | BA10: 0.65 | BB10: 0.5
A11: Equity | B11: International Small Cap Equity | C11: MSCI EAFE Small Cap | D11: 0.0602 | E11: 0.1767 | F11: 0.81 | G11: 0.78 | H11: 0.86 | I11: 0.73 | J11: 0.81 | K11: 0.86 | L11: 0.97 | M11: 1 | N11: 0.88 | O11: 0.029 | P11: -0.2512 | Q11: -0.1061 | R11: -0.2692 | S11: -0.276 | T11: 0.38 | U11: 0.36 | V11: 0.27 | W11: 0.17 | X11: -0.05671 | Y11: -0.05956 | Z11: 0.36 | AA11: 0.011 | AB11: -0.0984 | AC11: 0.67 | AD11: 0.62 | AE11: 0.44 | AF11: 0.32 | AG11: 0.64 | AH11: 0.61 | AI11: 0.64 | AJ11: 0.71 | AK11: 0.71 | AL11: 0.81 | AM11: 0.94 | AN11: 0.84 | AO11: 0.3 | AP11: 0.77 | AQ11: -0.06391 | AR11: 0.5 | AS11: 0.83 | AT11: 0.44 | AU11: 0.13 | AV11: 0.44 | AW11: 0.26 | AX11: 0.58 | AY11: 0.71 | AZ11: 0.83 | BA11: 0.55 | BB11: 0.5
A12: Equity | B12: Emerging Equity | C12: MSCI Emerging | D12: 0.0851 | E12: 0.222 | F12: 0.85 | G12: 0.77 | H12: 0.71 | I12: 0.71 | J12: 0.65 | K12: 0.92 | L12: 0.91 | M12: 0.88 | N12: 1 | O12: 0.067 | P12: -0.2165 | Q12: -0.03659 | R12: -0.212 | S12: -0.2323 | T12: 0.35 | U12: 0.41 | V12: 0.33 | W12: 0.26 | X12: -0.009693 | Y12: -0.03248 | Z12: 0.38 | AA12: 0.019 | AB12: -0.03117 | AC12: 0.78 | AD12: 0.58 | AE12: 0.45 | AF12: 0.35 | AG12: 0.53 | AH12: 0.63 | AI12: 0.7 | AJ12: 0.77 | AK12: 0.68 | AL12: 0.8 | AM12: 0.82 | AN12: 0.74 | AO12: 0.32 | AP12: 0.76 | AQ12: -0.04135 | AR12: 0.5 | AS12: 0.8 | AT12: 0.34 | AU12: 0.065 | AV12: 0.28 | AW12: 0.12 | AX12: 0.57 | AY12: 0.7 | AZ12: 0.75 | BA12: 0.59 | BB12: 0.5
A13: Fixed Income | B13: U.S. Aggregate | C13: Bloomberg Barclays U.S. Aggregate | D13: 0.027 | E13: 0.0298 | F13: -0.04839 | G13: -0.04154 | H13: -0.01844 | I13: -0.08298 | J13: -0.115 | K13: 0.0098 | L13: 0.03 | M13: 0.029 | N13: 0.067 | O13: 1 | P13: 0.9 | Q13: 0.16 | R13: 0.89 | S13: 0.83 | T13: 0.9 | U13: 0.92 | V13: 0.88 | W13: 0.8 | X13: 1 | Y13: 0.97 | Z13: 0.43 | AA13: 0.7 | AB13: 0.6 | AC13: 0.2 | AD13: -0.01902 | AE13: 0. 51 | AF13: 0.51 | AG13: 0.35 | AH13: 0.43 | AI13: 0.36 | AJ13: 0.36 | AK13: 0.066 | AL13: 0 | AM13: -0.05475 | AN13: -0.06156 | AO13: 0.25 | AP13: 0.084 | AQ13: 0.29 | AR13: 0.056 | AS13: -0.01083 | AT13: -0.03922 | AU13: -0.08367 | AV13: 0.13 | AW13: -0.3712 | AX13: 0.25 | AY13: 0.23 | AZ13: -0.06594 | BA13: -0.09034 | BB13: 0.011
A14: Fixed Income | B14: U.S. Treasury | C14: Bloomberg Barclays U.S. Treasury | D14: 0.0229 | E14: 0.0461 | F14: -0.3259 | G14: -0.312 | H14: -0.3171 | I14: -0.3121 | J14: -0.3466 | K14: -0.287 | L14: -0.244 | M14: -0.2512 | N14: -0.2165 | O14: 0.9 | P14: 1 | Q14: 0.21 | R14: 0.87 | S14: 0.93 | T14: 0.6 | U14: 0.6 | V14: 0.64 | W14: 0.64 | X14: 0.91 | Y14: 0.82 | Z14: 0.18 | AA14: 0.52 | AB14: 0.49 | AC14: -0.212 | AD14: -0.3587 | AE14: 0.37 | AF14: 0.42 | AG14: 0.13 | AH14: 0.18 | AI14: 0.049 | AJ14: 0.083 | AK14: -0.2273 | AL14: -0.2913 | AM14: -0.3334 | AN14: -0.3704 | AO14: 0.19 | AP14: -0.281 | AQ14: 0.36 | AR14: -0.1276 | AS14: -0.2687 | AT14: -0.1747 | AU14: -0.0958 | AV14: 0.13 | AW14: -0.1992 | AX14: -0.0211 | AY14: -0.0651 | AZ14: -0.3026 | BA14: -0.2711 | BB14: -0.2439
A15: Fixed Income | B15: U.S. Treasury Bills | C15: Bloomberg Barclays U.S. Treasury Bills 3-6 Month | D15: 0.0191 | E15: 0.0064 | F15: -0.1002 | G15: -0.1114 | H15: -0.1059 | I15: -0.0982 | J15: -0.09018 | K15: -0.0942 | L15: -0.06931 | M15: -0.1061 | N15: -0.03659 | O15: 0.16 | P15: 0.21 | Q15: 1 | R15: 0.3 | S15: 0.048 | T15: 0 | U15: 0.05 | V15: -0.04932 | W15: 0.093 | X15: 0.27 | Y15: 0.28 | Z15: -0.04588 | AA15: 0.043 | AB15: 0.3 | AC15: -0.1432 | AD15: -0.1503 | AE15: 0.075 | AF15: 0.084 | AG15: 0.019 | AH15: -0.01901 | AI15: -0.0549 | AJ15: 0.063 | AK15: 0.13 | AL15: 0.033 | AM15: 0.031 | AN15: 0.019 | AO15: 0.2 | AP15: 0.0093 | AQ15: 0.062 | AR15: 0.079 | AS15: 0 | AT15: -0.01945 | AU15: -0.02751 | AV15: 0.3 | AW15: -0.31 | AX15: -0.05741 | AY15: -0.06362 | AZ15: -0.06444 | BA15: -0.1315 | BB15: 0.021
A16: Fixed Income | B16: U.S. Intermediate Treasury | C16: Bloomberg Barclays U.S. Intermediate Treasury | D16: 0.0216 | E16: 0.031 | F16: -0.329 | G16: -0.3053 | H16: -0.3 | I16: -0.3397 | J16: -0.405 | K16: -0.3056 | L16: -0.2538 | M16: -0.2692 | N16: -0.212 | O16: 0.89 | P16: 0.87 | Q16: 0.3 | R16: 1 | S16: 0.8 | T16: 0.53 | U16: 0.57 | V16: 0.5 | W16: 0.64 | X16: 0.97 | Y16: 0.84 | Z16: 0.12 | AA16: 0.54 | AB16: 0.53 | AC16: -0.2132 | AD16: -0.418 | AE16: 0.44 | AF16: 0.46 | AG16: 0.17 | AH16: 0.16 | AI16: 0.041 | AJ16: 0.11 | AK16: -0.2087 | AL16: -0.2773 | AM16: -0.3247 | AN16: -0.3322 | AO16: 0.19 | AP16: -0.2576 | AQ16: 0.3 | AR16: -0.07404 | AS16: -0.2278 | AT16: -0.1789 | AU16: -0.1459 | AV16: 0.17 | AW16: -0.1887 | AX16: -0.03858 | AY16: -0.07663 | AZ16: -0.2948 | BA16: -0.2796 | BB16: -0.2119
A17: Fixed Income | B17: U.S. Long Treasury | C17: Bloomberg Barclays U.S. Long Treasury | D17: 0.0197 | E17: 0.1264 | F17: -0.2988 | G17: -0.3162 | H17: -0.306 | I17: -0.3582 | J17: -0.3859 | K17: -0.3216 | L17: -0.3051 | M17: -0.276 | N17: -0.2323 | O17: 0.83 | P17: 0.93 | Q17: 0.048 | R17: 0.8 | S17: 1 | T17: 0.56 | U17: 0.47 | V17: 0.67 | W17: 0.6 | X17: 0.69 | Y17: 0.7 | Z17: 0.16 | AA17: 0.53 | AB17: 0.35 | AC17: -0.1966 | AD17: -0.3146 | AE17: 0.22 | AF17: 0.31 | AG17: 0 | AH17: 0.19 | AI17: 0.042 | AJ17: 0.032 | AK17: -0.2318 | AL17: -0.3151 | AM17: -0.371 | AN17: -0.404 | AO17: 0.15 | AP17: -0.269 | AQ17: 0.36 | AR17: -0.2088 | AS17: -0.308 | AT17: -0.2281 | AU17: -0.06964 | AV17: -0.009967 | AW17: -0.2084 | AX17: 0.02 | AY17: -0.03612 | AZ17: -0.3105 | BA17: -0.2418 | BB17: -0.266
A18: Fixed Income | B18: U.S. Investment Grade Credit | C18: Bloomberg Barclays U.S. Credit | D18: 0.035 | E18: 0.0525 | F18: 0.24 | G18: 0.25 | H18: 0.26 | I18: 0.19 | J18: 0.16 | K18: 0.28 | L18: 0.32 | M18: 0.38 | N18: 0.35 | O18: 0.9 | P18: 0.6 | Q18: 0 | R18: 0.53 | S18: 0.56 | T18: 1 | U18: 0.9 | V18: 0.97 | W18: 0.7 | X18: 0.69 | Y18: 0.69 | Z18: 0.53 | AA18: 0.63 | AB18: 0.49 | AC18: 0.53 | AD18: 0.32 | AE18: 0.55 | AF18: 0.53 | AG18: 0.53 | AH18: 0.67 | AI18: 0.58 | AJ18: 0.56 | AK18: 0.35 | AL18: 0.3 | AM18: 0.26 | AN18: 0.25 | AO18: 0.31 | AP18: 0.41 | AQ18: 0.17 | AR18: 0.21 | AS18: 0.27 | AT18: 0.049 | AU18: 0 | AV18: 0.09 | AW18: -0.436 | AX18: 0.43 | AY18: 0.5 | AZ18: 0.2 | BA18: 0.12 | BB18: 0.25
A19: Fixed Income | B19: U.S. Intermediate Investment Grade Credit | C19: Bloomberg Barclays U.S. Intermediate Credit | D19: 0.0286 | E19: 0.0404 | F19: 0.24 | G19: 0.27 | H19: 0.29 | I19: 0.19 | J19: 0.18 | K19: 0.35 | L19: 0.38 | M19: 0.36 | N19: 0.41 | O19: 0.92 | P19: 0.6 | Q19: 0.05 | R19: 0.57 | S19: 0.47 | T19: 0.9 | U19: 1 | V19: 0.78 | W19: 0.8 | X19: 0.79 | Y19: 0.68 | Z19: 0.5 | AA19: 0.61 | AB19: 0.62 | AC19: 0.53 | AD19: 0.33 | AE19: 0.56 | AF19: 0.59 | AG19: 0.63 | AH19: 0.67 | AI19: 0.68 | AJ19: 0.55 | AK19: 0.39 | AL19: 0.33 | AM19: 0.33 | AN19: 0.29 | AO19: 0.27 | AP19: 0.52 | AQ19: 0.15 | AR19: 0.27 | AS19: 0.26 | AT19: 0.09 | AU19: -0.009352 | AV19: 0.13 | AW19: -0.363 | AX19: 0.4 | AY19: 0.46 | AZ19: 0.23 | BA19: 0.11 | BB19: 0.26
A20: Fixed Income | B20: U.S. Long Investment Grade Credit | C20: Bloomberg Barclays U.S. Long Credit | D20: 0.0393 | E20: 0.0995 | F20: 0.21 | G20: 0.21 | H20: 0.23 | I20: 0.18 | J20: 0.13 | K20: 0.27 | L20: 0.3 | M20: 0.27 | N20: 0.33 | O20: 0.88 | P20: 0.64 | Q20: -0.04932 | R20: 0.5 | S20: 0.67 | T20: 0.97 | U20: 0.78 | V20: 1 | W20: 0.7 | X20: 0.74 | Y20: 0.66 | Z20: 0.5 | AA20: 0.6 | AB20: 0.39 | AC20: 0.46 | AD20: 0.26 | AE20: 0.52 | AF20: 0.48 | AG20: 0.45 | AH20: 0.6 | AI20: 0.59 | AJ20: 0.47 | AK20: 0.24 | AL20: 0.23 | AM20: 0.2 | AN20: 0.2 | AO20: 0.25 | AP20: 0.35 | AQ20: 0.19 | AR20: 0.14 | AS20: 0.22 | AT20: -0.01022 | AU20: 0 | AV20: 0.064 | AW20: -0.3371 | AX20: 0.42 | AY20: 0.47 | AZ20: 0.17 | BA20: 0.1 | BB20: 0.17
A21: Fixed Income | B21: U.S. TIPS | C21: Bloomberg Barclays U.S. Inflation Linked Bonds | D21: 0.02 | E21: 0.0557 | F21: 0.064 | G21: 0.083 | H21: 0.12 | I21: 0.02 | J21: 0.021 | K21: 0.16 | L21: 0.17 | M21: 0.17 | N21: 0.26 | O21: 0.8 | P21: 0.64 | Q21: 0.093 | R21: 0.64 | S21: 0.6 | T21: 0.7 | U21: 0.8 | V21: 0.7 | W21: 1 | X21: 0.77 | Y21: 0.62 | Z21: 0.42 | AA21: 0.53 | AB21: 0.49 | AC21: 0.34 | AD21: 0.16 | AE21: 0.55 | AF21: 0.55 | AG21: 0.52 | AH21: 0.56 | AI21: 0.46 | AJ21: 0.47 | AK21: 0.2 | AL21: 0.17 | AM21: 0.11 | AN21: 0.1 | AO21: 0.28 | AP21: 0.28 | AQ21: 0.22 | AR21: 0.28 | AS21: 0.22 | AT21: 0.2 | AU21: -0.0528 | AV21: 0.23 | AW21: -0.2395 | AX21: 0.28 | AY21: 0.35 | AZ21: 0.1 | BA21: 0.02 | BB21: 0.13
A22: Fixed Income | B22: U.S. Agencies | C22: Bloomberg Barclays U.S. Agencies | D22: 0.0248 | E22: 0.0299 | F22: -0.1369 | G22: -0.1096 | H22: -0.1025 | I22: -0.138 | J22: -0.1729 | K22: -0.08073 | L22: -0.04366 | M22: -0.05671 | N22: -0.009693 | O22: 1 | P22: 0.91 | Q22: 0.27 | R22: 0.97 | S22: 0.69 | T22: 0.69 | U22: 0.79 | V22: 0.74 | W22: 0.77 | X22: 1 | Y22: 0.92 | Z22: 0.35 | AA22: 0.57 | AB22: 0.65 | AC22: 0.054 | AD22: -0.1626 | AE22: 0.5 | AF22: 0.56 | AG22: 0.34 | AH22: 0.33 | AI22: 0.26 | AJ22: 0.3 | AK22: -0.009052 | AL22: -0.06953 | AM22: -0.09908 | AN22: -0.1323 | AO22: 0.24 | AP22: -0.0214 | AQ22: 0.26 | AR22: 0.049 | AS22: -0.04068 | AT22: -0.0995 | AU22: -0.109 | AV22: 0.23 | AW22: -0.2597 | AX22: 0.12 | AY22: 0.11 | AZ22: -0.1619 | BA22: -0.1613 | BB22: -0.02109
A23: Fixed Income | B23: U.S. MBS | C23: Bloomberg Barclays U.S. MBS | D23: 0.0258 | E23: 0.0228 | F23: -0.1273 | G23: -0.125 | H23: -0.114 | I23: -0.1799 | J23: -0.215 | K23: -0.09871 | L23: -0.05725 | M23: -0.05956 | N23: -0.03248 | O23: 0.97 | P23: 0.82 | Q23: 0.28 | R23: 0.84 | S23: 0.7 | T23: 0.69 | U23: 0.68 | V23: 0.66 | W23: 0.62 | X23: 0.92 | Y23: 1 | Z23: 0.19 | AA23: 0.57 | AB23: 0.53 | AC23: 0.037 | AD23: -0.135 | AE23: 0.38 | AF23: 0.43 | AG23: 0.26 | AH23: 0.38 | AI23: 0.28 | AJ23: 0.2 | AK23: -0.03226 | AL23: -0.07922 | AM23: -0.1236 | AN23: -0.1397 | AO23: 0.19 | AP23: -0.01933 | AQ23: 0.18 | AR23: 0 | AS23: -0.07551 | AT23: -0.08411 | AU23: -0.1437 | AV23: 0.09 | AW23: -0.2724 | AX23: 0.09 | AY23: 0.1 | AZ23: -0.1211 | BA23: -0.1399 | BB23: -0.06537
A24: Fixed Income | B24: U.S. Investment Grade CMBS | C24: Bloomberg Barclays Investment Grade CMBS | D24: 0.0277 | E24: 0.0765 | F24: 0.39 | G24: 0.4 | H24: 0.39 | I24: 0.35 | J24: 0.32 | K24: 0.37 | L24: 0.37 | M24: 0.36 | N24: 0.38 | O24: 0.43 | P24: 0.18 | Q24: -0.04588 | R24: 0.12 | S24: 0.16 | T24: 0.53 | U24: 0.5 | V24: 0.5 | W24: 0.42 | X24: 0.35 | Y24: 0.19 | Z24: 1 | AA24: 0.33 | AB24: 0.23 | AC24: 0.67 | AD24: 0.5 | AE24: 0.37 | AF24: 0.34 | AG24: 0.44 | AH24: 0.44 | AI24: 0.4 | AJ24: 0.44 | AK24: 0.32 | AL24: 0.32 | AM24: 0.34 | AN24: 0.32 | AO24: 0.11 | AP24: 0.44 | AQ24: 0.029 | AR24: 0.23 | AS24: 0.22 | AT24: 0.45 | AU24: 0.038 | AV24: 0.29 | AW24: -0.1104 | AX24: 0.59 | AY24: 0.56 | AZ24: 0.38 | BA24: 0.21 | BB24: 0.27
A25: Fixed Income | B25: U.S. Intermediate Municipal | C25: S&P Municipal Bond Intermediate | D25: 0.0276 | E25: 0.034 | F25: -0.04354 | G25: -0.0293 | H25: 0 | I25: -0.06356 | J25: -0.06468 | K25: -0.009987 | L25: 0 | M25: 0.011 | N25: 0.019 | O25: 0.7 | P25: 0.52 | Q25: 0.043 | R25: 0.54 | S25: 0.53 | T25: 0.63 | U25: 0.61 | V25: 0.6 | W25: 0.53 | X25: 0.57 | Y25: 0.57 | Z25: 0.33 | AA25: 1 | AB25: 0.83 | AC25: 0.23 | AD25: 0.11 | AE25: 0.33 | AF25: 0.34 | AG25: 0.21 | AH25: 0.38 | AI25: 0.28 | AJ25: 0.26 | AK25: 0.061 | AL25: 0.018 | AM25: -0.02899 | AN25: -0.02092 | AO25: 0.15 | AP25: 0.14 | AQ25: 0.2 | AR25: -0.0365 | AS25: -0.04153 | AT25: 0.0093 | AU25: -0.0917 | AV25: -0.0219 | AW25: -0.3291 | AX25: 0.2 | AY25: 0.18 | AZ25: -0.03109 | BA25: -0.06641 | BB25: 0.14
... A28: Fixed Income | B28: U.S. Bank Loans | C28: CSFB Leveraged Loan | D28: 0.0486 | E28: 0.0548 | F28: 0.49 | G28: 0.58 | H28: 0.6 | I28: 0.56 | J28: 0.55 | K28: 0.53 | L28: 0.54 | M28: 0.62 | N28: 0.58 | O28: -0.01902 | P28: -0.3587 | Q28: -0.1503 | R28: -0.418 | S28: -0.3146 | T28: 0.32 | U28: 0.33 | V28: 0.26 | W28: 0.16 | X28: -0.1626 | Y28: -0.135 | Z28: 0.5 | AA28: 0.11 | AB28: -0.02057 | AC28: 0.85 | AD28: 1 | AE28: 0.1 | AF28: 0.0095 | AG28: 0.38 | AH28: 0.4 | AI28: 0.49 | AJ28: 0.36 | AK28: 0.64 | AL28: 0.6 | AM28: 0.6 | AN28: 0.72 | AO28: 0.038 | AP28: 0.87 | AQ28: -0.1562 | AR28: 0.39 | AS28: 0.42 | AT28: 0.73 | AU28: 0.18 | AV28: 0.049 | AW28: -0.2556 | AX28: 0.5 | AY28: 0.54 | AZ28: 0.56 | BA28: 0.36 | BB28: 0.51
A29: Fixed Income | B29: Global Aggregate Ex-US | C29: Bloomberg Barclays Global Aggregate Ex-USD | D29: 0.0044 | E29: 0.0738 | F29: 0.27 | G29: 0.23 | H29: 0.27 | I29: 0.18 | J29: 0.19 | K29: 0.35 | L29: 0.45 | M29: 0.44 | N29: 0.45 | O29: 0. 51 | P29: 0.37 | Q29: 0.075 | R29: 0.44 | S29: 0.22 | T29: 0.55 | U29: 0.56 | V29: 0.52 | W29: 0.55 | X29: 0.5 | Y29: 0.38 | Z29: 0.37 | AA29: 0.33 | AB29: 0.32 | AC29: 0.34 | AD29: 0.1 | AE29: 1 | AF29: 1 | AG29: 0.9 | AH29: 0.43 | AI29: 0.43 | AJ29: 0.55 | AK29: 0.21 | AL29: 0.28 | AM29: 0.27 | AN29: 0.25 | AO29: 0.25 | AP29: 0.24 | AQ29: 0.12 | AR29: 0.48 | AS29: 0.45 | AT29: 0.12 | AU29: 0 | AV29: 0.43 | AW29: 0.21 | AX29: 0.36 | AY29: 0.48 | AZ29: 0.2 | BA29: 0.1 | BB29: 0.22
A30: Fixed Income | B30: Global Treasury Ex-US | C30: Bloomberg Barclays Global Treasury Ex-USD | D30: 0.0021 | E30: 0.0791 | F30: 0.16 | G30: 0.16 | H30: 0.16 | I30: 0.11 | J30: 0.092 | K30: 0.3 | L30: 0.32 | M30: 0.32 | N30: 0.35 | O30: 0.51 | P30: 0.42 | Q30: 0.084 | R30: 0.46 | S30: 0.31 | T30: 0.53 | U30: 0.59 | V30: 0.48 | W30: 0.55 | X30: 0.56 | Y30: 0.43 | Z30: 0.34 | AA30: 0.34 | AB30: 0.3 | AC30: 0.27 | AD30: 0.0095 | AE30: 1 | AF30: 1 | AG30: 0.83 | AH30: 0.38 | AI30: 0.34 | AJ30: 0.56 | AK30: 0.15 | AL30: 0.17 | AM30: 0.16 | AN30: 0.13 | AO30: 0.25 | AP30: 0.13 | AQ30: 0.17 | AR30: 0.43 | AS30: 0.36 | AT30: 0.043 | AU30: -0.0191 | AV30: 0.4 | AW30: 0.19 | AX30: 0.3 | AY30: 0.4 | AZ30: 0.11 | BA30: 0.048 | BB30: 0.18
A31: Fixed Income | B31: Global Corporate Ex-US | C31: Bloomberg Barclays Global Corporate Ex-USD | D31: 0.0147 | E31: 0.0869 | F31: 0.47 | G31: 0.49 | H31: 0.5 | I31: 0.38 | J31: 0.39 | K31: 0.6 | L31: 0.73 | M31: 0.64 | N31: 0.53 | O31: 0.35 | P31: 0.13 | Q31: 0.019 | R31: 0.17 | S31: 0 | T31: 0.53 | U31: 0.63 | V31: 0.45 | W31: 0.52 | X31: 0.34 | Y31: 0.26 | Z31: 0.44 | AA31: 0.21 | AB31: 0.2 | AC31: 0.55 | AD31: 0.38 | AE31: 0.9 | AF31: 0.83 | AG31: 1 | AH31: 0.5 | AI31: 0.5 | AJ31: 0.6 | AK31: 0.48 | AL31: 0.52 | AM31: 0.52 | AN31: 0.45 | AO31: 0.23 | AP31: 0.48 | AQ31: 0 | AR31: 0.6 | AS31: 0.56 | AT31: 0.26 | AU31: 0.061 | AV31: 0.44 | AW31: 0.19 | AX31: 0.44 | AY31: 0.57 | AZ31: 0.4 | BA31: 0.25 | BB31: 0.35
A32: Fixed Income | B32: Emerging Markets Sovereign USD | C32: Bloomberg Barclays EM USD Sovereign | D32: 0.0522 | E32: 0.09828 | F32: 0.53 | G32: 0.54 | H32: 0.57 | I32: 0.45 | J32: 0.45 | K32: 0.7 | L32: 0.61 | M32: 0.61 | N32: 0.63 | O32: 0.43 | P32: 0.18 | Q32: -0.01901 | R32: 0.16 | S32: 0.19 | T32: 0.67 | U32: 0.67 | V32: 0.6 | W32: 0.56 | X32: 0.33 | Y32: 0.38 | Z32: 0.44 | AA32: 0.38 | AB32: 0.26 | AC32: 0.71 | AD32: 0.4 | AE32: 0.43 | AF32: 0.38 | AG32: 0.5 | AH32: 1 | AI32: 0.87 | AJ32: 0.81 | AK32: 0.53 | AL32: 0.6 | AM32: 0.5 | AN32: 0.57 | AO32: 0.26 | AP32: 0.6 | AQ32: 0 | AR32: 0.4 | AS32: 0.59 | AT32: 0.27 | AU32: 0.032 | AV32: 0.31 | AW32: 0.049 | AX32: 0.49 | AY32: 0.68 | AZ32: 0.5 | BA32: 0.36 | BB32: 0.33
A33: Fixed Income | B33: Emerging Markets Corporate USD | C33: Bloomberg Barclays EM USD Corporate | D33: 0.0523 | E33: 0.1202 | F33: 0.57 | G33: 0.59 | H33: 0.63 | I33: 0.57 | J33: 0.5 | K33: 0.65 | L33: 0.56 | M33: 0.64 | N33: 0.7 | O33: 0.36 | P33: 0.049 | Q33: -0.0549 | R33: 0.041 | S33: 0.042 | T33: 0.58 | U33: 0.68 | V33: 0.59 | W33: 0.46 | X33: 0.26 | Y33: 0.28 | Z33: 0.4 | AA33: 0.28 | AB33: 0.22 | AC33: 0.79 | AD33: 0.49 | AE33: 0.43 | AF33: 0.34 | AG33: 0.5 | AH33: 0.87 | AI33: 1 | AJ33: 0.69 | AK33: 0.63 | AL33: 0.7 | AM33: 0.62 | AN33: 0.59 | AO33: 0.22 | AP33: 0.6 | AQ33: -0.06365 | AR33: 0.44 | AS33: 0.63 | AT33: 0.37 | AU33: 0.037 | AV33: 0.26 | AW33: -0.02918 | AX33: 0.48 | AY33: 0.69 | AZ33: 0.57 | BA33: 0.41 | BB33: 0.39
A34: Fixed Income | B34: Emerging Markets Sovereign Local Currency | C34: Bloomberg Barclays EM Local Currency Government | D34: 0.0535 | E34: 0.1193 | F34: 0.63 | G34: 0.58 | H34: 0.65 | I34: 0.54 | J34: 0.53 | K34: 0.7 | L34: 0.7 | M34: 0.71 | N34: 0.77 | O34: 0.36 | P34: 0.083 | Q34: 0.063 | R34: 0.11 | S34: 0.032 | T34: 0.56 | U34: 0.55 | V34: 0.47 | W34: 0.47 | X34: 0.3 | Y34: 0.2 | Z34: 0.44 | AA34: 0.26 | AB34: 0.18 | AC34: 0.69 | AD34: 0.36 | AE34: 0.55 | AF34: 0.56 | AG34: 0.6 | AH34: 0.81 | AI34: 0.69 | AJ34: 1 | AK34: 0.52 | AL34: 0.6 | AM34: 0.65 | AN34: 0.54 | AO34: 0.3 | AP34: 0.54 | AQ34: -0.01978 | AR34: 0.5 | AS34: 0.76 | AT34: 0.25 | AU34: 0.036 | AV34: 0.42 | AW34: 0.14 | AX34: 0.7 | AY34: 0.67 | AZ34: 0.56 | BA34: 0.45 | BB34: 0.49
A35: Alternatives | B35: Absolute Return | C35: HFRX Global Hedge Fund | D35: 0.0435 | E35: 0.0511 | F35: 0.63 | G35: 0.7 | H35: 0.68 | I35: 0.63 | J35: 0.72 | K35: 0.69 | L35: 0.7 | M35: 0.71 | N35: 0.68 | O35: 0.066 | P35: -0.2273 | Q35: 0.13 | R35: -0.2087 | S35: -0.2318 | T35: 0.35 | U35: 0.39 | V35: 0.24 | W35: 0.2 | X35: -0.009052 | Y35: -0.03226 | Z35: 0.32 | AA35: 0.061 | AB35: 0 | AC35: 0.6 | AD35: 0.64 | AE35: 0.21 | AF35: 0.15 | AG35: 0.48 | AH35: 0.53 | AI35: 0.63 | AJ35: 0.52 | AK35: 1 | AL35: 0.82 | AM35: 0.79 | AN35: 0.89 | AO35: 0.54 | AP35: 0.89 | AQ35: 0.15 | AR35: 0.51 | AS35: 0.65 | AT35: 0.52 | AU35: 0.17 | AV35: 0.35 | AW35: -0.03811 | AX35: 0.43 | AY35: 0.52 | AZ35: 0.7 | BA35: 0.56 | BB35: 0.54
A36: Alternatives | B36: Hedge Funds | C36: HFRI Fund Weighted Composite | D36: 0.0405 | E36: 0.0622 | F36: 0.81 | G36: 0.79 | H36: 0.93 | I36: 0.8 | J36: 0.81 | K36: 0.95 | L36: 0.81 | M36: 0.81 | N36: 0.8 | O36: 0 | P36: -0.2913 | Q36: 0.033 | R36: -0.2773 | S36: -0.3151 | T36: 0.3 | U36: 0.33 | V36: 0.23 | W36: 0.17 | X36: -0.06953 | Y36: -0.07922 | Z36: 0.32 | AA36: 0.018 | AB36: -0.04372 | AC36: 0.72 | AD36: 0.6 | AE36: 0.28 | AF36: 0.17 | AG36: 0.52 | AH36: 0.6 | AI36: 0.7 | AJ36: 0.6 | AK36: 0.82 | AL36: 1 | AM36: 0.99 | AN36: 0.88 | AO36: 0.55 | AP36: 0.76 | AQ36: 0.071 | AR36: 0.58 | AS36: 0.73 | AT36: 0.46 | AU36: 0.1 | AV36: 0.34 | AW36: 0.084 | AX36: 0.5 | AY36: 0.74 | AZ36: 0.85 | BA36: 0.67 | BB36: 0.55
A37: Alternatives | B37: Hedge Funds – Equity Hedge | C37: HFRI Equity Hedge | D37: 0.0523 | E37: 0.0861 | F37: 0.85 | G37: 0.89 | H37: 0.95 | I37: 0.86 | J37: 0.93 | K37: 0.83 | L37: 0.93 | M37: 0.94 | N37: 0.82 | O37: -0.05475 | P37: -0.3334 | Q37: 0.031 | R37: -0.3247 | S37: -0.371 | T37: 0.26 | U37: 0.33 | V37: 0.2 | W37: 0.11 | X37: -0.09908 | Y37: -0.1236 | Z37: 0.34 | AA37: -0.02899 | AB37: -0.07931 | AC37: 0.8 | AD37: 0.6 | AE37: 0.27 | AF37: 0.16 | AG37: 0.52 | AH37: 0.5 | AI37: 0.62 | AJ37: 0.65 | AK37: 0.79 | AL37: 0.99 | AM37: 1 | AN37: 0.98 | AO37: 0.44 | AP37: 0.79 | AQ37: -0.04005 | AR37: 0.58 | AS37: 0.9 | AT37: 0.45 | AU37: 0.13 | AV37: 0.36 | AW37: 0.14 | AX37: 0.55 | AY37: 0.72 | AZ37: 0.81 | BA37: 0.7 | BB37: 0.5
A38: Alternatives | B38: Hedge Funds – Event Driven | C38: HFRI Event Driven | D38: 0.0425 | E38: 0.0624 | F38: 0.72 | G38: 0.75 | H38: 0.9 | I38: 0.71 | J38: 0.89 | K38: 0.78 | L38: 0.76 | M38: 0.84 | N38: 0.74 | O38: -0.06156 | P38: -0.3704 | Q38: 0.019 | R38: -0.3322 | S38: -0.404 | T38: 0.25 | U38: 0.29 | V38: 0.2 | W38: 0.1 | X38: -0.1323 | Y38: -0.1397 | Z38: 0.32 | AA38: -0.02092 | AB38: -0.06952 | AC38: 0.73 | AD38: 0.72 | AE38: 0.25 | AF38: 0.13 | AG38: 0.45 | AH38: 0.57 | AI38: 0.59 | AJ38: 0.54 | AK38: 0.89 | AL38: 0.88 | AM38: 0.98 | AN38: 1 | AO38: 0.37 | AP38: 0.8 | AQ38: -0.08548 | AR38: 0.49 | AS38: 0.8 | AT38: 0.54 | AU38: 0.18 | AV38: 0.35 | AW38: 0.055 | AX38: 0.44 | AY38: 0.63 | AZ38: 0.78 | BA38: 0.55 | BB38: 0.6
A39: Alternatives | B39: Hedge Funds – Macro | C39: HFRI Macro | D39: 0.0348 | E39: 0.0503 | F39: 0.22 | G39: 0.21 | H39: 0.27 | I39: 0.22 | J39: 0.25 | K39: 0.3 | L39: 0.3 | M39: 0.3 | N39: 0.32 | O39: 0.25 | P39: 0.19 | Q39: 0.2 | R39: 0.19 | S39: 0.15 | T39: 0.31 | U39: 0.27 | V39: 0.25 | W39: 0.28 | X39: 0.24 | Y39: 0.19 | Z39: 0.11 | AA39: 0.15 | AB39: 0.16 | AC39: 0.14 | AD39: 0.038 | AE39: 0.25 | AF39: 0.25 | AG39: 0.23 | AH39: 0.26 | AI39: 0.22 | AJ39: 0.3 | AK39: 0.54 | AL39: 0.55 | AM39: 0.44 | AN39: 0.37 | AO39: 1 | AP39: 0.27 | AQ39: 0.75 | AR39: 0.31 | AS39: 0.4 | AT39: -0.01081 | AU39: -0.107 | AV39: 0.22 | AW39: -0.04914 | AX39: 0.17 | AY39: 0.27 | AZ39: 0.25 | BA39: 0.25 | BB39: 0.2
A40: Alternatives | B40: Hedge Funds – Relative Value | C40: HFRI Relative Value | D40: 0.0339 | E40: 0.0412 | F40: 0.64 | G40: 0.7 | H40: 0.8 | I40: 0.63 | J40: 0.66 | K40: 0.7 | L40: 0.68 | M40: 0.77 | N40: 0.76 | O40: 0.084 | P40: -0.281 | Q40: 0.0093 | R40: -0.2576 | S40: -0.269 | T40: 0.41 | U40: 0.52 | V40: 0.35 | W40: 0.28 | X40: -0.0214 | Y40: -0.01933 | Z40: 0.44 | AA40: 0.14 | AB40: 0.064 | AC40: 0.86 | AD40: 0.87 | AE40: 0.24 | AF40: 0.13 | AG40: 0.48 | AH40: 0.6 | AI40: 0.6 | AJ40: 0.54 | AK40: 0.89 | AL40: 0.76 | AM40: 0.79 | AN40: 0.8 | AO40: 0.27 | AP40: 1 | AQ40: -0.08589 | AR40: 0.53 | AS40: 0.64 | AT40: 0.58 | AU40: 0.15 | AV40: 0.23 | AW40: -0.1687 | AX40: 0.47 | AY40: 0.59 | AZ40: 0.72 | BA40: 0.47 | BB40: 0.6
A41: Alternatives | B41: Hedge Funds – Managed Futures | C41: SG CTA Index | D41: 0.0419 | E41: 0.0845 | F41: -0.09348 | G41: -0.08217 | H41: -0.07699 | I41: -0.103 | J41: -0.105 | K41: -0.07463 | L41: -0.06168 | M41: -0.06391 | N41: -0.04135 | O41: 0.29 | P41: 0.36 | Q41: 0.062 | R41: 0.3 | S41: 0.36 | T41: 0.17 | U41: 0.15 | V41: 0.19 | W41: 0.22 | X41: 0.26 | Y41: 0.18 | Z41: 0.029 | AA41: 0.2 | AB41: 0.17 | AC41: -0.1459 | AD41: -0.1562 | AE41: 0.12 | AF41: 0.17 | AG41: 0 | AH41: 0 | AI41: -0.06365 | AJ41: -0.01978 | AK41: 0.15 | AL41: 0.071 | AM41: -0.04005 | AN41: -0.08548 | AO41: 0.75 | AP41: -0.08589 | AQ41: 1 | AR41: -0.00934 | AS41: -0.01911 | AT41: -0.1496 | AU41: -0.1077 | AV41: -0.02739 | AW41: -0.06321 | AX41: 0.018 | AY41: 0.011 | AZ41: -0.07608 | BA41: -0.05897 | BB41: -0.07113
... A52: Alternatives | B52: Energy Infrastructure | C52: Alerian MLP Infrastructure | D52: 0.0648 | E52: 0.2017 | F52: 0.51 | G52: 0.49 | H52: 0.47 | I52: 0.47 | J52: 0.47 | K52: 0.51 | L52: 0.5 | M52: 0.5 | N52: 0.5 | O52: 0.011 | P52: -0.2439 | Q52: 0.021 | R52: -0.2119 | S52: -0.266 | T52: 0.25 | U52: 0.26 | V52: 0.17 | W52: 0.13 | X52: -0.02109 | Y52: -0.06537 | Z52: 0.27 | AA52: 0.14 | AB52: 0.1 | AC52: 0.63 | AD52: 0.51 | AE52: 0.22 | AF52: 0.18 | AG52: 0.35 | AH52: 0.33 | AI52: 0.39 | AJ52: 0.49 | AK52: 0.54 | AL52: 0.55 | AM52: 0.5 | AN52: 0.6 | AO52: 0.2 | AP52: 0.6 | AQ52: -0.07113 | AR52: 0.45 | AS52: 0.56 | AT52: 0.32 | AU52: 0.085 | AV52: 0.25 | AW52: -0.08587 | AX52: 0.29 | AY52: 0.41 | AZ52: 0.51 | BA52: 0.29 | BB52: 1

Sheet Index Returns
A1: Index | B1: US Large Cap | C1: Dev ex US | D1: EM | E1: UST | F1: IG Corp Bond | G1: REITs
A2: 36585 | B2: -0.0096300858 | C2: 0.002358393 | D2: 0.002358393 | E2: -0.021243057 | F2: 0.0056581651 | G2: -0.028660244
A3: 36616 | B3: 0.045823842 | C3: 0.02320719 | D3: 0.02320719 | E3: -0.040337182 | F3: 0.0077365716 | G3: -0.0033643129
A4: 36644 | B4: -0.0072999361 | C4: -0.027483517 | D4: -0.027483517 | E4: -0.042514904 | F4: 0.006436328 | G4: 0.055385687
A5: 36677 | B5: -0.028714769 | C5: -0.040368748 | D5: -0.040368748 | E5: 0.075106628 | F5: -0.022235327 | G5: 0.037859265
A6: 36707 | B6: 0.035217747 | C6: 0.042731255 | D6: 0.042731255 | E6: -0.053285341 | F6: 0.027657174 | G6: 0.03229656
A7: 36738 | B7: 0.006699123 | C7: -0.0088846429 | D7: -0.0088846429 | E7: -0.0070970628 | F7: 0.013513591 | G7: 0.046883912
A8: 36769 | B8: 0.0073634753 | C8: -0.028449637 | D8: -0.028449637 | E8: -0.037646687 | F8: 0.012964601 | G8: 0.017230577
A9: 36798 | B9: -6.7194634e-06 | C9: -0.031463387 | D9: -0.031463387 | E9: -0.0046492537 | F9: 0.0056364753 | G9: -0.0099409611
A10: 36830 | B10: -0.057550427 | C10: -0.044308938 | D10: -0.044308938 | E10: -0.010420516 | F10: 0.0039797154 | G10: -0.027840079
A11: 36860 | B11: -0.014561193 | C11: -0.0051056651 | D11: -0.0051056651 | E11: -0.0037341299 | F11: 0.0038094361 | G11: -0.00075495409
A12: 36889 | B12: -0.033936814 | C12: -0.0084341113 | D12: -0.0084341113 | E12: -0.083370815 | F12: 0.021878738 | G12: 0.062460936
A13: 36922 | B13: 0.003531884 | C13: -0.0036590616 | D13: -0.0036590616 | E13: -0.015179395 | F13: 0.020431286 | G13: 0.025456538
... A216: 43098 | B216: 0.026366374 | C216: 0.0055423655 | D216: 0.0055545478 | E216: 0.021049044 | F216: 0.004107695 | G216: 0.0096416201

Sheet CME - AM
A1: Capital Market Expectations - averaged across Asset Managers (AM1 & AM2)
A2: Step 2: average each asset's expected return & volatility across the two managers. Step 3: optimistic scenario (return x 1.10, volatility x 0.90). Step 4: average pairwise correlations.
B3: Optimistic adj. - Return | D3: 1.1 | F3: Optimistic adj. - Vol | H3: 0.9
F4: Expected Return | J4: Expected Volatility
B5: Our Assets | C5: ETF | D5: AM1 name | E5: AM2 name | F5: AM1 | G5: AM2 | H5: Average | I5: Optimistic | J5: AM1 | K5: AM2 | L5: Average | M5: Optimistic
B6: US Large Cap | C6: WPETF | D6: U.S. Large Cap | E6: Russell 3000 | F6: =VLOOKUP($D6,'CME - AM1'!$B:$D,2,FALSE) | G6: =VLOOKUP($E6,'CME - AM2'!$C:$E,2,FALSE) | H6: =AVERAGE(F6:G6) | I6: =H6*$D$3 | J6: =VLOOKUP($D6,'CME - AM1'!$B:$D,3,FALSE) | K6: =VLOOKUP($E6,'CME - AM2'!$C:$E,3,FALSE) | L6: =AVERAGE(J6:K6) | M6: =L6*$H$3
B7: Dev ex US | C7: LPDM | D7: EAFE Equity | E7: MSCI EAFE | F7: =VLOOKUP($D7,'CME - AM1'!$B:$D,2,FALSE) | G7: =VLOOKUP($E7,'CME - AM2'!$C:$E,2,FALSE) | H7: =AVERAGE(F7:G7) | I7: =H7*$D$3 | J7: =VLOOKUP($D7,'CME - AM1'!$B:$D,3,FALSE) | K7: =VLOOKUP($E7,'CME - AM2'!$C:$E,3,FALSE) | L7: =AVERAGE(J7:K7) | M7: =L7*$H$3
B8: EM | C8: LPEM | D8: Emerging Markets Equity | E8: MSCI Emerging | F8: =VLOOKUP($D8,'CME - AM1'!$B:$D,2,FALSE) | G8: =VLOOKUP($E8,'CME - AM2'!$C:$E,2,FALSE) | H8: =AVERAGE(F8:G8) | I8: =H8*$D$3 | J8: =VLOOKUP($D8,'CME - AM1'!$B:$D,3,FALSE) | K8: =VLOOKUP($E8,'CME - AM2'!$C:$E,3,FALSE) | L8: =AVERAGE(J8:K8) | M8: =L8*$H$3
B9: UST | C9: SABE | D9: U.S. Long Treasuries | E9: Bloomberg Barclays U.S. Treasury | F9: =VLOOKUP($D9,'CME - AM1'!$B:$D,2,FALSE) | G9: =VLOOKUP($E9,'CME - AM2'!$C:$E,2,FALSE) | H9: =AVERAGE(F9:G9) | I9: =H9*$D$3 | J9: =VLOOKUP($D9,'CME - AM1'!$B:$D,3,FALSE) | K9: =VLOOKUP($E9,'CME - AM2'!$C:$E,3,FALSE) | L9: =AVERAGE(J9:K9) | M9: =L9*$H$3
B10: US IG Corp Bond | C10: KUSIG | D10: U.S. Inv Grade Corporate Bonds | E10: Bloomberg Barclays U.S. Credit | F10: =VLOOKUP($D10,'CME - AM1'!$B:$D,2,FALSE) | G10: =VLOOKUP($E10,'CME - AM2'!$C:$E,2,FALSE) | H10: =AVERAGE(F10:G10) | I10: =H10*$D$3 | J10: =VLOOKUP($D10,'CME - AM1'!$B:$D,3,FALSE) | K10: =VLOOKUP($E10,'CME - AM2'!$C:$E,3,FALSE) | L10: =AVERAGE(J10:K10) | M10: =L10*$H$3
B11: REITs | C11: WPREI | D11: U.S. REITs | E11: FTSE NAREIT Equity | F11: =VLOOKUP($D11,'CME - AM1'!$B:$D,2,FALSE) | G11: =VLOOKUP($E11,'CME - AM2'!$C:$E,2,FALSE) | H11: =AVERAGE(F11:G11) | I11: =H11*$D$3 | J11: =VLOOKUP($D11,'CME - AM1'!$B:$D,3,FALSE) | K11: =VLOOKUP($E11,'CME - AM2'!$C:$E,3,FALSE) | L11: =AVERAGE(J11:K11) | M11: =L11*$H$3
F14: Correlation Matrix - AM1
D15: Asset | E15: Index # | F15: =$D$16 | G15: =$D$17 | H15: =$D$18 | I15: =$D$19 | J15: =$D$20 | K15: =$D$21
D16: =D6 | E16: =MATCH(D16,'CME - AM1'!$B$4:$B$54,0) | F16: =INDEX('CME - AM1'!$E$4:$BC$54,MAX($E16,INDEX($E$16:$E$21,1)),MIN($E16,INDEX($E$16:$E$21,1))) | G16: =INDEX('CME - AM1'!$E$4:$BC$54,MAX($E16,INDEX($E$16:$E$21,2)),MIN($E16,INDEX($E$16:$E$21,2))) | H16: =INDEX('CME - AM1'!$E$4:$BC$54,MAX($E16,INDEX($E$16:$E$21,3)),MIN($E16,INDEX($E$16:$E$21,3))) | I16: =INDEX('CME - AM1'!$E$4:$BC$54,MAX($E16,INDEX($E$16:$E$21,4)),MIN($E16,INDEX($E$16:$E$21,4))) | J16: =INDEX('CME - AM1'!$E$4:$BC$54,MAX($E16,INDEX($E$16:$E$21,5)),MIN($E16,INDEX($E$16:$E$21,5))) | K16: =INDEX('CME - AM1'!$E$4:$BC$54,MAX($E16,INDEX($E$16:$E$21,6)),MIN($E16,INDEX($E$16:$E$21,6)))
D17: =D7 | E17: =MATCH(D17,'CME - AM1'!$B$4:$B$54,0) | F17: =INDEX('CME - AM1'!$E$4:$BC$54,MAX($E17,INDEX($E$16:$E$21,1)),MIN($E17,INDEX($E$16:$E$21,1))) | G17: =INDEX('CME - AM1'!$E$4:$BC$54,MAX($E17,INDEX($E$16:$E$21,2)),MIN($E17,INDEX($E$16:$E$21,2))) | H17: =INDEX('CME - AM1'!$E$4:$BC$54,MAX($E17,INDEX($E$16:$E$21,3)),MIN($E17,INDEX($E$16:$E$21,3))) | I17: =INDEX('CME - AM1'!$E$4:$BC$54,MAX($E17,INDEX($E$16:$E$21,4)),MIN($E17,INDEX($E$16:$E$21,4))) | J17: =INDEX('CME - AM1'!$E$4:$BC$54,MAX($E17,INDEX($E$16:$E$21,5)),MIN($E17,INDEX($E$16:$E$21,5))) | K17: =INDEX('CME - AM1'!$E$4:$BC$54,MAX($E17,INDEX($E$16:$E$21,6)),MIN($E17,INDEX($E$16:$E$21,6)))
D18: =D8 | E18: =MATCH(D18,'CME - AM1'!$B$4:$B$54,0) | F18: =INDEX('CME - AM1'!$E$4:$BC$54,MAX($E18,INDEX($E$16:$E$21,1)),MIN($E18,INDEX($E$16:$E$21,1))) | G18: =INDEX('CME - AM1'!$E$4:$BC$54,MAX($E18,INDEX($E$16:$E$21,2)),MIN($E18,INDEX($E$16:$E$21,2))) | H18: =INDEX('CME - AM1'!$E$4:$BC$54,MAX($E18,INDEX($E$16:$E$21,3)),MIN($E18,INDEX($E$16:$E$21,3))) | I18: =INDEX('CME - AM1'!$E$4:$BC$54,MAX($E18,INDEX($E$16:$E$21,4)),MIN($E18,INDEX($E$16:$E$21,4))) | J18: =INDEX('CME - AM1'!$E$4:$BC$54,MAX($E18,INDEX($E$16:$E$21,5)),MIN($E18,INDEX($E$16:$E$21,5))) | K18: =INDEX('CME - AM1'!$E$4:$BC$54,MAX($E18,INDEX($E$16:$E$21,6)),MIN($E18,INDEX($E$16:$E$21,6)))
D19: =D9 | E19: =MATCH(D19,'CME - AM1'!$B$4:$B$54,0) | F19: =INDEX('CME - AM1'!$E$4:$BC$54,MAX($E19,INDEX($E$16:$E$21,1)),MIN($E19,INDEX($E$16:$E$21,1))) | G19: =INDEX('CME - AM1'!$E$4:$BC$54,MAX($E19,INDEX($E$16:$E$21,2)),MIN($E19,INDEX($E$16:$E$21,2))) | H19: =INDEX('CME - AM1'!$E$4:$BC$54,MAX($E19,INDEX($E$16:$E$21,3)),MIN($E19,INDEX($E$16:$E$21,3))) | I19: =INDEX('CME - AM1'!$E$4:$BC$54,MAX($E19,INDEX($E$16:$E$21,4)),MIN($E19,INDEX($E$16:$E$21,4))) | J19: =INDEX('CME - AM1'!$E$4:$BC$54,MAX($E19,INDEX($E$16:$E$21,5)),MIN($E19,INDEX($E$16:$E$21,5))) | K19: =INDEX('CME - AM1'!$E$4:$BC$54,MAX($E19,INDEX($E$16:$E$21,6)),MIN($E19,INDEX($E$16:$E$21,6)))
D20: =D10 | E20: =MATCH(D20,'CME - AM1'!$B$4:$B$54,0) | F20: =INDEX('CME - AM1'!$E$4:$BC$54,MAX($E20,INDEX($E$16:$E$21,1)),MIN($E20,INDEX($E$16:$E$21,1))) | G20: =INDEX('CME - AM1'!$E$4:$BC$54,MAX($E20,INDEX($E$16:$E$21,2)),MIN($E20,INDEX($E$16:$E$21,2))) | H20: =INDEX('CME - AM1'!$E$4:$BC$54,MAX($E20,INDEX($E$16:$E$21,3)),MIN($E20,INDEX($E$16:$E$21,3))) | I20: =INDEX('CME - AM1'!$E$4:$BC$54,MAX($E20,INDEX($E$16:$E$21,4)),MIN($E20,INDEX($E$16:$E$21,4))) | J20: =INDEX('CME - AM1'!$E$4:$BC$54,MAX($E20,INDEX($E$16:$E$21,5)),MIN($E20,INDEX($E$16:$E$21,5))) | K20: =INDEX('CME - AM1'!$E$4:$BC$54,MAX($E20,INDEX($E$16:$E$21,6)),MIN($E20,INDEX($E$16:$E$21,6)))
D21: =D11 | E21: =MATCH(D21,'CME - AM1'!$B$4:$B$54,0) | F21: =INDEX('CME - AM1'!$E$4:$BC$54,MAX($E21,INDEX($E$16:$E$21,1)),MIN($E21,INDEX($E$16:$E$21,1))) | G21: =INDEX('CME - AM1'!$E$4:$BC$54,MAX($E21,INDEX($E$16:$E$21,2)),MIN($E21,INDEX($E$16:$E$21,2))) | H21: =INDEX('CME - AM1'!$E$4:$BC$54,MAX($E21,INDEX($E$16:$E$21,3)),MIN($E21,INDEX($E$16:$E$21,3))) | I21: =INDEX('CME - AM1'!$E$4:$BC$54,MAX($E21,INDEX($E$16:$E$21,4)),MIN($E21,INDEX($E$16:$E$21,4))) | J21: =INDEX('CME - AM1'!$E$4:$BC$54,MAX($E21,INDEX($E$16:$E$21,5)),MIN($E21,INDEX($E$16:$E$21,5))) | K21: =INDEX('CME - AM1'!$E$4:$BC$54,MAX($E21,INDEX($E$16:$E$21,6)),MIN($E21,INDEX($E$16:$E$21,6)))
F23: Correlation Matrix - AM2
D24: Asset | E24: Index # | F24: =$D$25 | G24: =$D$26 | H24: =$D$27 | I24: =$D$28 | J24: =$D$29 | K24: =$D$30
D25: =E6 | E25: =MATCH(D25,'CME - AM2'!$C$4:$C$52,0) | F25: =INDEX('CME - AM2'!$F$4:$BB$52,MAX($E25,INDEX($E$25:$E$30,1)),MIN($E25,INDEX($E$25:$E$30,1))) | G25: =INDEX('CME - AM2'!$F$4:$BB$52,MAX($E25,INDEX($E$25:$E$30,2)),MIN($E25,INDEX($E$25:$E$30,2))) | H25: =INDEX('CME - AM2'!$F$4:$BB$52,MAX($E25,INDEX($E$25:$E$30,3)),MIN($E25,INDEX($E$25:$E$30,3))) | I25: =INDEX('CME - AM2'!$F$4:$BB$52,MAX($E25,INDEX($E$25:$E$30,4)),MIN($E25,INDEX($E$25:$E$30,4))) | J25: =INDEX('CME - AM2'!$F$4:$BB$52,MAX($E25,INDEX($E$25:$E$30,5)),MIN($E25,INDEX($E$25:$E$30,5))) | K25: =INDEX('CME - AM2'!$F$4:$BB$52,MAX($E25,INDEX($E$25:$E$30,6)),MIN($E25,INDEX($E$25:$E$30,6)))
D26: =E7 | E26: =MATCH(D26,'CME - AM2'!$C$4:$C$52,0) | F26: =INDEX('CME - AM2'!$F$4:$BB$52,MAX($E26,INDEX($E$25:$E$30,1)),MIN($E26,INDEX($E$25:$E$30,1))) | G26: =INDEX('CME - AM2'!$F$4:$BB$52,MAX($E26,INDEX($E$25:$E$30,2)),MIN($E26,INDEX($E$25:$E$30,2))) | H26: =INDEX('CME - AM2'!$F$4:$BB$52,MAX($E26,INDEX($E$25:$E$30,3)),MIN($E26,INDEX($E$25:$E$30,3))) | I26: =INDEX('CME - AM2'!$F$4:$BB$52,MAX($E26,INDEX($E$25:$E$30,4)),MIN($E26,INDEX($E$25:$E$30,4))) | J26: =INDEX('CME - AM2'!$F$4:$BB$52,MAX($E26,INDEX($E$25:$E$30,5)),MIN($E26,INDEX($E$25:$E$30,5))) | K26: =INDEX('CME - AM2'!$F$4:$BB$52,MAX($E26,INDEX($E$25:$E$30,6)),MIN($E26,INDEX($E$25:$E$30,6)))
D27: =E8 | E27: =MATCH(D27,'CME - AM2'!$C$4:$C$52,0) | F27: =INDEX('CME - AM2'!$F$4:$BB$52,MAX($E27,INDEX($E$25:$E$30,1)),MIN($E27,INDEX($E$25:$E$30,1))) | G27: =INDEX('CME - AM2'!$F$4:$BB$52,MAX($E27,INDEX($E$25:$E$30,2)),MIN($E27,INDEX($E$25:$E$30,2))) | H27: =INDEX('CME - AM2'!$F$4:$BB$52,MAX($E27,INDEX($E$25:$E$30,3)),MIN($E27,INDEX($E$25:$E$30,3))) | I27: =INDEX('CME - AM2'!$F$4:$BB$52,MAX($E27,INDEX($E$25:$E$30,4)),MIN($E27,INDEX($E$25:$E$30,4))) | J27: =INDEX('CME - AM2'!$F$4:$BB$52,MAX($E27,INDEX($E$25:$E$30,5)),MIN($E27,INDEX($E$25:$E$30,5))) | K27: =INDEX('CME - AM2'!$F$4:$BB$52,MAX($E27,INDEX($E$25:$E$30,6)),MIN($E27,INDEX($E$25:$E$30,6)))
D28: =E9 | E28: =MATCH(D28,'CME - AM2'!$C$4:$C$52,0) | F28: =INDEX('CME - AM2'!$F$4:$BB$52,MAX($E28,INDEX($E$25:$E$30,1)),MIN($E28,INDEX($E$25:$E$30,1))) | G28: =INDEX('CME - AM2'!$F$4:$BB$52,MAX($E28,INDEX($E$25:$E$30,2)),MIN($E28,INDEX($E$25:$E$30,2))) | H28: =INDEX('CME - AM2'!$F$4:$BB$52,MAX($E28,INDEX($E$25:$E$30,3)),MIN($E28,INDEX($E$25:$E$30,3))) | I28: =INDEX('CME - AM2'!$F$4:$BB$52,MAX($E28,INDEX($E$25:$E$30,4)),MIN($E28,INDEX($E$25:$E$30,4))) | J28: =INDEX('CME - AM2'!$F$4:$BB$52,MAX($E28,INDEX($E$25:$E$30,5)),MIN($E28,INDEX($E$25:$E$30,5))) | K28: =INDEX('CME - AM2'!$F$4:$BB$52,MAX($E28,INDEX($E$25:$E$30,6)),MIN($E28,INDEX($E$25:$E$30,6)))
D29: =E10 | E29: =MATCH(D29,'CME - AM2'!$C$4:$C$52,0) | F29: =INDEX('CME - AM2'!$F$4:$BB$52,MAX($E29,INDEX($E$25:$E$30,1)),MIN($E29,INDEX($E$25:$E$30,1))) | G29: =INDEX('CME - AM2'!$F$4:$BB$52,MAX($E29,INDEX($E$25:$E$30,2)),MIN($E29,INDEX($E$25:$E$30,2))) | H29: =INDEX('CME - AM2'!$F$4:$BB$52,MAX($E29,INDEX($E$25:$E$30,3)),MIN($E29,INDEX($E$25:$E$30,3))) | I29: =INDEX('CME - AM2'!$F$4:$BB$52,MAX($E29,INDEX($E$25:$E$30,4)),MIN($E29,INDEX($E$25:$E$30,4))) | J29: =INDEX('CME - AM2'!$F$4:$BB$52,MAX($E29,INDEX($E$25:$E$30,5)),MIN($E29,INDEX($E$25:$E$30,5))) | K29: =INDEX('CME - AM2'!$F$4:$BB$52,MAX($E29,INDEX($E$25:$E$30,6)),MIN($E29,INDEX($E$25:$E$30,6)))
D30: =E11 | E30: =MATCH(D30,'CME - AM2'!$C$4:$C$52,0) | F30: =INDEX('CME - AM2'!$F$4:$BB$52,MAX($E30,INDEX($E$25:$E$30,1)),MIN($E30,INDEX($E$25:$E$30,1))) | G30: =INDEX('CME - AM2'!$F$4:$BB$52,MAX($E30,INDEX($E$25:$E$30,2)),MIN($E30,INDEX($E$25:$E$30,2))) | H30: =INDEX('CME - AM2'!$F$4:$BB$52,MAX($E30,INDEX($E$25:$E$30,3)),MIN($E30,INDEX($E$25:$E$30,3))) | I30: =INDEX('CME - AM2'!$F$4:$BB$52,MAX($E30,INDEX($E$25:$E$30,4)),MIN($E30,INDEX($E$25:$E$30,4))) | J30: =INDEX('CME - AM2'!$F$4:$BB$52,MAX($E30,INDEX($E$25:$E$30,5)),MIN($E30,INDEX($E$25:$E$30,5))) | K30: =INDEX('CME - AM2'!$F$4:$BB$52,MAX($E30,INDEX($E$25:$E$30,6)),MIN($E30,INDEX($E$25:$E$30,6)))
F32: Average Correlation Matrix (AM1 & AM2)
E33: Asset | F33: =$B$6 | G33: =$B$7 | H33: =$B$8 | I33: =$B$9 | J33: =$B$10 | K33: =$B$11
E34: =$B$6 | F34: =AVERAGE(F16,F25) | G34: =AVERAGE(G16,G25) | H34: =AVERAGE(H16,H25) | I34: =AVERAGE(I16,I25) | J34: =AVERAGE(J16,J25) | K34: =AVERAGE(K16,K25)
E35: =$B$7 | F35: =AVERAGE(F17,F26) | G35: =AVERAGE(G17,G26) | H35: =AVERAGE(H17,H26) | I35: =AVERAGE(I17,I26) | J35: =AVERAGE(J17,J26) | K35: =AVERAGE(K17,K26)
E36: =$B$8 | F36: =AVERAGE(F18,F27) | G36: =AVERAGE(G18,G27) | H36: =AVERAGE(H18,H27) | I36: =AVERAGE(I18,I27) | J36: =AVERAGE(J18,J27) | K36: =AVERAGE(K18,K27)
E37: =$B$9 | F37: =AVERAGE(F19,F28) | G37: =AVERAGE(G19,G28) | H37: =AVERAGE(H19,H28) | I37: =AVERAGE(I19,I28) | J37: =AVERAGE(J19,J28) | K37: =AVERAGE(K19,K28)
E38: =$B$10 | F38: =AVERAGE(F20,F29) | G38: =AVERAGE(G20,G29) | H38: =AVERAGE(H20,H29) | I38: =AVERAGE(I20,I29) | J38: =AVERAGE(J20,J29) | K38: =AVERAGE(K20,K29)
E39: =$B$11 | F39: =AVERAGE(F21,F30) | G39: =AVERAGE(G21,G30) | H39: =AVERAGE(H21,H30) | I39: =AVERAGE(I21,I30) | J39: =AVERAGE(J21,J30) | K39: =AVERAGE(K21,K30)

Sheet SAA with CME
A1: Strategic Asset Allocation - Six Asset Portfolio (Optimistic CME)
B3: Correlation | C3: ='CME - AM'!F33 | D3: ='CME - AM'!G33 | E3: ='CME - AM'!H33 | F3: ='CME - AM'!I33 | G3: ='CME - AM'!J33 | H3: ='CME - AM'!K33 | J3: Portfolio objective & constraints
B4: ='CME - AM'!E34 | C4: ='CME - AM'!F34 | D4: ='CME - AM'!G34 | E4: ='CME - AM'!H34 | F4: ='CME - AM'!I34 | G4: ='CME - AM'!J34 | H4: ='CME - AM'!K34 | J4: Objective | N4: Maximise expected return
B5: ='CME - AM'!E35 | C5: ='CME - AM'!F35 | D5: ='CME - AM'!G35 | E5: ='CME - AM'!H35 | F5: ='CME - AM'!I35 | G5: ='CME - AM'!J35 | H5: ='CME - AM'!K35 | J5: Risk tolerance (Medium) - max volatility | N5: 0.15
B6: ='CME - AM'!E36 | C6: ='CME - AM'!F36 | D6: ='CME - AM'!G36 | E6: ='CME - AM'!H36 | F6: ='CME - AM'!I36 | G6: ='CME - AM'!J36 | H6: ='CME - AM'!K36 | J6: Minimum weight per asset class (Portfolio B) | N6: 0.1
B7: ='CME - AM'!E37 | C7: ='CME - AM'!F37 | D7: ='CME - AM'!G37 | E7: ='CME - AM'!H37 | F7: ='CME - AM'!I37 | G7: ='CME - AM'!J37 | H7: ='CME - AM'!K37 | J7: Risk-free rate (for Sharpe) | N7: 0.03
B8: ='CME - AM'!E38 | C8: ='CME - AM'!F38 | D8: ='CME - AM'!G38 | E8: ='CME - AM'!H38 | F8: ='CME - AM'!I38 | G8: ='CME - AM'!J38 | H8: ='CME - AM'!K38
B9: ='CME - AM'!E39 | C9: ='CME - AM'!F39 | D9: ='CME - AM'!G39 | E9: ='CME - AM'!H39 | F9: ='CME - AM'!I39 | G9: ='CME - AM'!J39 | H9: ='CME - AM'!K39 | J9: Weights in blue are Solver outputs: Max I18/I30, by changing C17:H17 / C29:H29,
J10: subject to: weights sum = 100%, volatility <= N5, weights >= 0 (A) or >= N6 (B).
B11: E Return | C11: =INDEX('CME - AM'!$I$6:$I$11,1) | D11: =INDEX('CME - AM'!$I$6:$I$11,2) | E11: =INDEX('CME - AM'!$I$6:$I$11,3) | F11: =INDEX('CME - AM'!$I$6:$I$11,4) | G11: =INDEX('CME - AM'!$I$6:$I$11,5) | H11: =INDEX('CME - AM'!$I$6:$I$11,6)
B12: Volatility | C12: =INDEX('CME - AM'!$M$6:$M$11,1) | D12: =INDEX('CME - AM'!$M$6:$M$11,2) | E12: =INDEX('CME - AM'!$M$6:$M$11,3) | F12: =INDEX('CME - AM'!$M$6:$M$11,4) | G12: =INDEX('CME - AM'!$M$6:$M$11,5) | H12: =INDEX('CME - AM'!$M$6:$M$11,6)
B15: Portfolio A - Max return, volatility <= 15%, long-only (weights >= 0)
C16: =C3 | D16: =D3 | E16: =E3 | F16: =F3 | G16: =G3 | H16: =H3 | I16: Total
B17: Weights | C17: 0.405265 | D17: 0 | E17: 0.513863 | F17: 0 | G17: 0.080872 | H17: 0 | I17: =SUM(C17:H17) | K17: Volatility within limit? | N17: =IF(I20<=$N$5+0.000001,"Yes","No")
B18: E Return | C18: =C17*C$11 | D18: =D17*D$11 | E18: =E17*E$11 | F18: =F17*F$11 | G18: =G17*G$11 | H18: =H17*H$11 | I18: =SUM(C18:H18) | K18: Weights sum to 100%? | N18: =IF(ABS(I17-1)<0.000001,"Yes","No")
H19: Variance | I19: {=MMULT(MMULT(C17:H17*$C$12:$H$12,$C$4:$H$9),TRANSPOSE(C17:H17*$C$12:$H$12))}
H20: Volatility | I20: =SQRT(I19)
H21: Risk-Free Rate | I21: =$N$7 | K21: Min weight >= 0? | N21: =IF(MIN(C17:H17)>=0,"Yes","No")
H22: Sharpe Ratio | I22: =(I18-I21)/I20
B23: Portfolio A hits the 15% volatility limit but is concentrated in only 3 asset classes - not fully diversified.
B25: Portfolio B (Selected SAA) - Max return, volatility <= 15%, each asset class >= 10%
C26: =C3 | D26: =D3 | E26: =E3 | F26: =F3 | G26: =G3 | H26: =H3 | I26: Total
B27: Weights | C27: 0.1 | D27: 0.1 | E27: 0.5 | F27: 0.1 | G27: 0.1 | H27: 0.1 | I27: =SUM(C27:H27) | K27: Volatility within limit? | N27: =IF(I30<=$N$5+0.000001,"Yes","No")
B28: E Return | C28: =C27*C$11 | D28: =D27*D$11 | E28: =E27*E$11 | F28: =F27*F$11 | G28: =G27*G$11 | H28: =H27*H$11 | I28: =SUM(C28:H28) | K28: Weights sum to 100%? | N28: =IF(ABS(I27-1)<0.000001,"Yes","No")
H29: Variance | I29: {=MMULT(MMULT(C27:H27*$C$12:$H$12,$C$4:$H$9),TRANSPOSE(C27:H27*$C$12:$H$12))}
H30: Volatility | I30: =SQRT(I29)
